<?xml version="1.0" ?>
<!-- =================================================================================== -->
<!-- |    This document was autogenerated by xacro from victor.urdf.xacro              | -->
<!-- |    EDITING THIS FILE BY HAND IS NOT RECOMMENDED                                 | -->
<!-- =================================================================================== -->
<robot name="victor" xmlns:xacro="http://www.ros.org/wiki/xacro">
  <material name="Black">
    <color rgba="0.0 0.0 0.0 1.0"/>
  </material>
  <material name="Blue">
    <color rgba="0.0 0.0 0.8 1.0"/>
  </material>
  <material name="Green">
    <color rgba="0.0 0.8 0.0 1.0"/>
  </material>
  <material name="Grey">
    <color rgba="0.4 0.4 0.4 1.0"/>
  </material>
  <material name="Orange">
    <color rgba="1.0 0.423529411765 0.0392156862745 1.0"/>
  </material>
  <material name="Brown">
    <color rgba="0.870588235294 0.811764705882 0.764705882353 1.0"/>
  </material>
  <material name="Red">
    <color rgba="0.8 0.0 0.0 1.0"/>
  </material>
  <material name="White">
    <color rgba="1.0 1.0 1.0 1.0"/>
  </material>
  <material name="LightGrey">
    <color rgba="0.7 0.7 0.7 1"/>
  </material>
  <material name="DarkGray">
    <color rgba="0.2 0.2 0.2 1"/>
  </material>
  <material name="DarkDarkGray">
    <color rgba="0.1 0.1 0.1 1"/>
  </material>
  <link name="victor_root"/>
  <joint name="victor_dummy_root_joint" type="fixed">
    <parent link="victor_root"/>
    <child link="victor_pedestal"/>
    <origin rpy="0 0 0" xyz="0 0 0"/>
    <axis xyz="0 0 1"/>
  </joint>
  <link name="victor_pedestal">
    <visual>
      <origin rpy="0 0 0" xyz="0 0 0.9245"/>
      <geometry>
        <mesh filename="package://victor_description/meshes/baxter_pedestal/pedestal_visual.stl"/>
      </geometry>
      <material name="DarkGray"/>
    </visual>
    <collision>
      <origin rpy="0 0 0" xyz="0 0 0.9245"/>
      <geometry>
        <mesh filename="package://victor_description/meshes/baxter_pedestal/pedestal_collision.stl"/>
      </geometry>
      <material name="DarkGray"/>
    </collision>
    <inertial>
      <origin rpy="0 0 0" xyz="0 0 0"/>
      <mass value="60.86397744"/>
      <inertia ixx="5.0635929" ixy="0.00103417" ixz="0.80199628" iyy="6.08689388" iyz="0.00105311" izz="4.96191932"/>
    </inertial>
  </link>
  <joint name="victor_base_plate_mount_joint" type="fixed">
    <parent link="victor_pedestal"/>
    <child link="victor_base_plate_mount"/>
    <origin rpy="0 0 0" xyz="0 0 0.863"/>
    <axis xyz="0 0 1"/>
  </joint>
  <link name="victor_base_plate_mount"/>
  <joint name="victor_base_plate_joint" type="fixed">
    <parent link="victor_base_plate_mount"/>
    <child link="victor_base_plate"/>
    <origin rpy="0 0 0" xyz="0 0 0"/>
    <axis xyz="0 0 1"/>
  </joint>
  <link name="victor_base_plate">
    <visual>
      <origin rpy="0 0 0" xyz="0 0 0"/>
      <geometry>
        <mesh filename="package://victor_description/meshes/torso/torso_visual.stl"/>
      </geometry>
      <material name="LightGrey"/>
    </visual>
    <collision>
      <origin rpy="0 0 0" xyz="0 0 0.2"/>
      <geometry>
        <!--<mesh filename="package://victor_description/meshes/torso_visual_model.stl"/>-->
        <cylinder length="0.7" radius="0.2"/>
      </geometry>
      <material name="LightGrey"/>
    </collision>
  </link>
  <joint name="victor_left_arm_mount_joint" type="fixed">
    <parent link="victor_base_plate"/>
    <child link="victor_left_arm_mount"/>
    <origin rpy="-1.5707963268 0 -0.785398163397448" xyz="-0.02 0.1384885 0.385"/>
    <axis xyz="0 0 1"/>
  </joint>
  <link name="victor_left_arm_mount">
    <collision>
      <origin rpy="0 0 0" xyz="0 0 -0.013"/>
      <geometry>
        <!--<mesh filename="package://victor_description/meshes/torso_visual_model.stl"/>-->
        <box size="0.31 0.31 0.032"/>
      </geometry>
      <material name="LightGrey"/>
    </collision>
  </link>
  <joint name="victor_right_arm_mount_joint" type="fixed">
    <parent link="victor_base_plate"/>
    <child link="victor_right_arm_mount"/>
    <origin rpy="1.5707963268 0 0.785398163397448" xyz="-0.02 -0.1384885 0.385"/>
    <axis xyz="0 0 1"/>
  </joint>
  <link name="victor_right_arm_mount">
    <collision>
      <origin rpy="0 0 0" xyz="0 0 -0.013"/>
      <geometry>
        <!--<mesh filename="package://victor_description/meshes/torso_visual_model.stl"/>-->
        <box size="0.31 0.31 0.032"/>
      </geometry>
      <material name="LightGrey"/>
    </collision>
  </link>
  <!--joint between {parent} and link_0-->
  <joint name="victor_left_arm_mount_victor_left_arm_joint" type="fixed">
    <origin rpy="0 0 0" xyz="0 0 0"/>
    <parent link="victor_left_arm_mount"/>
    <child link="victor_left_arm_link_0"/>
  </joint>
  <link name="victor_left_arm_link_0">
    <inertial>
      <origin rpy="0 0 0" xyz="-0.1 0 0.07"/>
      <mass value="5"/>
      <inertia ixx="0.05" ixy="0" ixz="0" iyy="0.06" iyz="0" izz="0.03"/>
    </inertial>
    <visual>
      <origin rpy="0 0 0" xyz="0 0 0"/>
      <geometry>
        <mesh filename="package://victor_description/meshes/iiwa7/visual/link_0.stl"/>
      </geometry>
      <material name="Grey"/>
    </visual>
    <collision>
      <origin rpy="0 0 0" xyz="0 0 0"/>
      <geometry>
        <mesh filename="package://victor_description/meshes/iiwa7/collision/link_0.stl"/>
      </geometry>
      <material name="Grey"/>
    </collision>
    <self_collision_checking>
      <origin rpy="0 0 0" xyz="0 0 0"/>
      <geometry>
        <capsule length="0.25" radius="0.15"/>
      </geometry>
    </self_collision_checking>
  </link>
  <!-- joint between link_0 and link_1 -->
  <joint name="victor_left_arm_joint_1" type="revolute">
    <parent link="victor_left_arm_link_0"/>
    <child link="victor_left_arm_link_1"/>
    <origin rpy="0 0 0" xyz="0 0 0.15"/>
    <axis xyz="0 0 1"/>
    <limit effort="300" lower="-2.96705972839" upper="2.96705972839" velocity="10"/>
    <safety_controller k_position="100" k_velocity="2" soft_lower_limit="-2.93215314335" soft_upper_limit="2.93215314335"/>
    <dynamics damping="0.5"/>
  </joint>
  <link name="victor_left_arm_link_1">
    <inertial>
      <origin rpy="0 0 0" xyz="0 -0.03 0.12"/>
      <mass value="3.4525"/>
      <inertia ixx="0.02183" ixy="0" ixz="0" iyy="0.007703" iyz="-0.003887" izz="0.02083"/>
    </inertial>
    <visual>
      <origin rpy="0 0 0" xyz="0 0 0.0075"/>
      <geometry>
        <mesh filename="package://victor_description/meshes/iiwa7/visual/link_1.stl"/>
      </geometry>
      <material name="Orange"/>
    </visual>
    <collision>
      <origin rpy="0 0 0" xyz="0 0 0.0075"/>
      <geometry>
        <mesh filename="package://victor_description/meshes/iiwa7/collision/link_1.stl"/>
      </geometry>
      <material name="Orange"/>
    </collision>
  </link>
  <joint name="victor_left_arm_joint_2" type="revolute">
    <parent link="victor_left_arm_link_1"/>
    <child link="victor_left_arm_link_2"/>
    <origin rpy="1.57079632679   0 3.14159265359" xyz="0 0 0.19"/>
    <axis xyz="0 0 1"/>
    <limit effort="300" lower="-2.09439510239" upper="2.09439510239" velocity="10"/>
    <safety_controller k_position="100" k_velocity="2" soft_lower_limit="-2.05948851735" soft_upper_limit="2.05948851735"/>
    <dynamics damping="0.5"/>
  </joint>
  <link name="victor_left_arm_link_2">
    <inertial>
      <origin rpy="0 0 0" xyz="0.0003 0.059 0.042"/>
      <mass value="3.4821"/>
      <inertia ixx="0.02076" ixy="0" ixz="-0.003626" iyy="0.02179" iyz="0" izz="0.00779"/>
    </inertial>
    <visual>
      <origin rpy="0 0 0" xyz="0 0 0"/>
      <geometry>
        <mesh filename="package://victor_description/meshes/iiwa7/visual/link_2.stl"/>
      </geometry>
      <material name="Orange"/>
    </visual>
    <collision>
      <origin rpy="0 0 0" xyz="0 0 0"/>
      <geometry>
        <mesh filename="package://victor_description/meshes/iiwa7/collision/link_2.stl"/>
      </geometry>
      <material name="Orange"/>
    </collision>
  </link>
  <joint name="victor_left_arm_joint_3" type="revolute">
    <parent link="victor_left_arm_link_2"/>
    <child link="victor_left_arm_link_3"/>
    <origin rpy="1.57079632679 0 3.14159265359" xyz="0 0.21 0"/>
    <axis xyz="0 0 1"/>
    <limit effort="300" lower="-2.96705972839" upper="2.96705972839" velocity="10"/>
    <safety_controller k_position="100" k_velocity="2" soft_lower_limit="-2.93215314335" soft_upper_limit="2.93215314335"/>
    <dynamics damping="0.5"/>
  </joint>
  <link name="victor_left_arm_link_3">
    <inertial>
      <origin rpy="0 0 0" xyz="0 0.03 0.13"/>
      <mass value="4.05623"/>
      <inertia ixx="0.03204" ixy="0" ixz="0" iyy="0.00972" iyz="0.006227" izz="0.03042"/>
    </inertial>
    <visual>
      <origin rpy="0 0 0" xyz="0 0 -0.026"/>
      <geometry>
        <mesh filename="package://victor_description/meshes/iiwa7/visual/link_3.stl"/>
      </geometry>
      <material name="Orange"/>
    </visual>
    <collision>
      <origin rpy="0 0 0" xyz="0 0 -0.026"/>
      <geometry>
        <mesh filename="package://victor_description/meshes/iiwa7/collision/link_3.stl"/>
      </geometry>
      <material name="Orange"/>
    </collision>
  </link>
  <joint name="victor_left_arm_joint_4" type="revolute">
    <parent link="victor_left_arm_link_3"/>
    <child link="victor_left_arm_link_4"/>
    <origin rpy="1.57079632679 0 0" xyz="0 0 0.19"/>
    <axis xyz="0 0 1"/>
    <limit effort="300" lower="-2.09439510239" upper="2.09439510239" velocity="10"/>
    <safety_controller k_position="100" k_velocity="2" soft_lower_limit="-2.05948851735" soft_upper_limit="2.05948851735"/>
    <dynamics damping="0.5"/>
  </joint>
  <link name="victor_left_arm_link_4">
    <inertial>
      <origin rpy="0 0 0" xyz="0 0.067 0.034"/>
      <mass value="3.4822"/>
      <inertia ixx="0.02178" ixy="0" ixz="0" iyy="0.02075" iyz="-0.003625" izz="0.007785"/>
    </inertial>
    <visual>
      <origin rpy="0 0 0" xyz="0 0 0"/>
      <geometry>
        <mesh filename="package://victor_description/meshes/iiwa7/visual/link_4.stl"/>
      </geometry>
      <material name="Orange"/>
    </visual>
    <collision>
      <origin rpy="0 0 0" xyz="0 0 0"/>
      <geometry>
        <mesh filename="package://victor_description/meshes/iiwa7/collision/link_4.stl"/>
      </geometry>
      <material name="Orange"/>
    </collision>
  </link>
  <joint name="victor_left_arm_joint_5" type="revolute">
    <parent link="victor_left_arm_link_4"/>
    <child link="victor_left_arm_link_5"/>
    <origin rpy="-1.57079632679 3.14159265359 0" xyz="0 0.21 0"/>
    <axis xyz="0 0 1"/>
    <limit effort="300" lower="-2.96705972839" upper="2.96705972839" velocity="10"/>
    <safety_controller k_position="100" k_velocity="2" soft_lower_limit="-2.93215314335" soft_upper_limit="2.93215314335"/>
    <dynamics damping="0.5"/>
  </joint>
  <link name="victor_left_arm_link_5">
    <inertial>
      <origin rpy="0 0 0" xyz="0.0001 0.021 0.076"/>
      <mass value="2.1633"/>
      <inertia ixx="0.01287" ixy="0" ixz="0" iyy="0.005708" iyz="-0.003946" izz="0.01112"/>
    </inertial>
    <visual>
      <origin rpy="0 0 0" xyz="0 0 -0.026"/>
      <geometry>
        <mesh filename="package://victor_description/meshes/iiwa7/visual/link_5.stl"/>
      </geometry>
      <material name="Orange"/>
    </visual>
    <collision>
      <origin rpy="0 0 0" xyz="0 0 -0.026"/>
      <geometry>
        <mesh filename="package://victor_description/meshes/iiwa7/collision/link_5.stl"/>
      </geometry>
      <material name="Orange"/>
    </collision>
  </link>
  <joint name="victor_left_arm_joint_6" type="revolute">
    <parent link="victor_left_arm_link_5"/>
    <child link="victor_left_arm_link_6"/>
    <origin rpy="1.57079632679 0 0" xyz="0 0.06070 0.19"/>
    <axis xyz="0 0 1"/>
    <limit effort="300" lower="-2.09439510239" upper="2.09439510239" velocity="10"/>
    <safety_controller k_position="100" k_velocity="2" soft_lower_limit="-2.05948851735" soft_upper_limit="2.05948851735"/>
    <dynamics damping="0.5"/>
  </joint>
  <link name="victor_left_arm_link_6">
    <inertial>
      <origin rpy="0 0 0" xyz="0 0.0006 0.0004"/>
      <mass value="2.3466"/>
      <inertia ixx="0.006509" ixy="0" ixz="0" iyy="0.006259" iyz="0.00031891" izz="0.004527"/>
    </inertial>
    <visual>
      <origin rpy="0 0 0" xyz="0 0 0"/>
      <geometry>
        <mesh filename="package://victor_description/meshes/iiwa7/visual/link_6.stl"/>
      </geometry>
      <material name="Orange"/>
    </visual>
    <collision>
      <origin rpy="0 0 0" xyz="0 0 0"/>
      <geometry>
        <mesh filename="package://victor_description/meshes/iiwa7/collision/link_6.stl"/>
      </geometry>
      <material name="Orange"/>
    </collision>
  </link>
  <joint name="victor_left_arm_joint_7" type="revolute">
    <parent link="victor_left_arm_link_6"/>
    <child link="victor_left_arm_link_7"/>
    <origin rpy="-1.57079632679 3.14159265359 0" xyz="0 0.081 0.06070"/>
    <axis xyz="0 0 1"/>
    <limit effort="300" lower="-3.05432619099" upper="3.05432619099" velocity="10"/>
    <safety_controller k_position="100" k_velocity="2" soft_lower_limit="-3.01941960595" soft_upper_limit="3.01941960595"/>
    <dynamics damping="0.5"/>
  </joint>
  <link name="victor_left_arm_link_7">
    <inertial>
      <origin rpy="0 0 0" xyz="0 0 0.02"/>
      <mass value="3.129"/>
      <inertia ixx="0.01464" ixy="0.0005912" ixz="0" iyy="0.01465" iyz="0" izz="0.002872"/>
    </inertial>
    <visual>
      <origin rpy="0 0 0" xyz="0 0 -0.0005"/>
      <geometry>
        <mesh filename="package://victor_description/meshes/iiwa7/visual/link_7_electric.stl"/>
      </geometry>
      <material name="Grey"/>
    </visual>
    <collision>
      <origin rpy="0 0 0" xyz="0 0 -0.0005"/>
      <geometry>
        <mesh filename="package://victor_description/meshes/iiwa7/collision/link_7_electric.stl"/>
      </geometry>
      <material name="Grey"/>
    </collision>
  </link>
  <joint name="victor_left_arm_joint_flange" type="fixed">
    <parent link="victor_left_arm_link_7"/>
    <child link="victor_left_arm_flange"/>
    <origin rpy="0 0 0" xyz="0 0 0.045"/>
  </joint>
  <link name="victor_left_arm_flange">
        </link>
  <!-- Our usage above has been tweaked to match Kuka's internal usage, so identity transform -->
  <joint name="victor_left_arm_flange_kuka_joint" type="fixed">
    <parent link="victor_left_arm_flange"/>
    <child link="victor_left_arm_flange_kuka"/>
    <origin rpy="0 0 0" xyz="0 0 0"/>
  </joint>
  <link name="victor_left_arm_flange_kuka">
        </link>
  <!-- Load Gazebo lib and set the robot namespace -->
  <gazebo>
    <plugin filename="libgazebo_ros_control.so" name="gazebo_ros_control">
      <robotNamespace>/victor_left_arm</robotNamespace>
    </plugin>
  </gazebo>
  <!-- Link0 -->
  <gazebo reference="iiwa_link_0">
    <material>Gazebo/Grey</material>
    <mu1>0.2</mu1>
    <mu2>0.2</mu2>
  </gazebo>
  <!-- Link1 -->
  <gazebo reference="iiwa_link_1">
    <material>Gazebo/Orange</material>
    <mu1>0.2</mu1>
    <mu2>0.2</mu2>
  </gazebo>
  <!-- Link2 -->
  <gazebo reference="iiwa_link_2">
    <material>Gazebo/Orange</material>
    <mu1>0.2</mu1>
    <mu2>0.2</mu2>
  </gazebo>
  <!-- Link3 -->
  <gazebo reference="iiwa_link_3">
    <material>Gazebo/Orange</material>
    <mu1>0.2</mu1>
    <mu2>0.2</mu2>
  </gazebo>
  <!-- Link4 -->
  <gazebo reference="iiwa_link_4">
    <material>Gazebo/Orange</material>
    <mu1>0.2</mu1>
    <mu2>0.2</mu2>
  </gazebo>
  <!-- Link5 -->
  <gazebo reference="iiwa_link_5">
    <material>Gazebo/Orange</material>
    <mu1>0.2</mu1>
    <mu2>0.2</mu2>
  </gazebo>
  <!-- Link6 -->
  <gazebo reference="iiwa_link_6">
    <material>Gazebo/Orange</material>
    <mu1>0.2</mu1>
    <mu2>0.2</mu2>
  </gazebo>
  <!-- Link7 -->
  <gazebo reference="iiwa_link_7">
    <material>Gazebo/Grey</material>
    <mu1>0.2</mu1>
    <mu2>0.2</mu2>
  </gazebo>
  <transmission name="iiwa_tran_1">
    <robotNamespace>/victor_left_arm</robotNamespace>
    <type>transmission_interface/SimpleTransmission</type>
    <joint name="iiwa_joint_1">
      <hardwareInterface>PositionJointInterface</hardwareInterface>
    </joint>
    <actuator name="iiwa_motor_1">
      <hardwareInterface>PositionJointInterface</hardwareInterface>
      <mechanicalReduction>1</mechanicalReduction>
    </actuator>
  </transmission>
  <transmission name="iiwa_tran_2">
    <robotNamespace>/victor_left_arm</robotNamespace>
    <type>transmission_interface/SimpleTransmission</type>
    <joint name="iiwa_joint_2">
      <hardwareInterface>PositionJointInterface</hardwareInterface>
    </joint>
    <actuator name="iiwa_motor_2">
      <hardwareInterface>PositionJointInterface</hardwareInterface>
      <mechanicalReduction>1</mechanicalReduction>
    </actuator>
  </transmission>
  <transmission name="iiwa_tran_3">
    <robotNamespace>/victor_left_arm</robotNamespace>
    <type>transmission_interface/SimpleTransmission</type>
    <joint name="iiwa_joint_3">
      <hardwareInterface>PositionJointInterface</hardwareInterface>
    </joint>
    <actuator name="iiwa_motor_3">
      <hardwareInterface>PositionJointInterface</hardwareInterface>
      <mechanicalReduction>1</mechanicalReduction>
    </actuator>
  </transmission>
  <transmission name="iiwa_tran_4">
    <robotNamespace>/victor_left_arm</robotNamespace>
    <type>transmission_interface/SimpleTransmission</type>
    <joint name="iiwa_joint_4">
      <hardwareInterface>PositionJointInterface</hardwareInterface>
    </joint>
    <actuator name="iiwa_motor_4">
      <hardwareInterface>PositionJointInterface</hardwareInterface>
      <mechanicalReduction>1</mechanicalReduction>
    </actuator>
  </transmission>
  <transmission name="iiwa_tran_5">
    <robotNamespace>/victor_left_arm</robotNamespace>
    <type>transmission_interface/SimpleTransmission</type>
    <joint name="iiwa_joint_5">
      <hardwareInterface>PositionJointInterface</hardwareInterface>
    </joint>
    <actuator name="iiwa_motor_5">
      <hardwareInterface>PositionJointInterface</hardwareInterface>
      <mechanicalReduction>1</mechanicalReduction>
    </actuator>
  </transmission>
  <transmission name="iiwa_tran_6">
    <robotNamespace>/victor_left_arm</robotNamespace>
    <type>transmission_interface/SimpleTransmission</type>
    <joint name="iiwa_joint_6">
      <hardwareInterface>PositionJointInterface</hardwareInterface>
    </joint>
    <actuator name="iiwa_motor_6">
      <hardwareInterface>PositionJointInterface</hardwareInterface>
      <mechanicalReduction>1</mechanicalReduction>
    </actuator>
  </transmission>
  <transmission name="iiwa_tran_7">
    <robotNamespace>/victor_left_arm</robotNamespace>
    <type>transmission_interface/SimpleTransmission</type>
    <joint name="iiwa_joint_7">
      <hardwareInterface>PositionJointInterface</hardwareInterface>
    </joint>
    <actuator name="iiwa_motor_7">
      <hardwareInterface>PositionJointInterface</hardwareInterface>
      <mechanicalReduction>1</mechanicalReduction>
    </actuator>
  </transmission>
  <joint name="victor_joint_left_arm_world_frame_kuka" type="fixed">
    <parent link="victor_left_arm_mount"/>
    <child link="victor_left_arm_world_frame_kuka"/>
    <origin rpy="1.57079632679 0 0" xyz="0 0 0"/>
  </joint>
  <link name="victor_left_arm_world_frame_kuka">
    </link>
  <!--joint between {parent} and link_0-->
  <joint name="victor_right_arm_mount_victor_right_arm_joint" type="fixed">
    <origin rpy="0 0 0" xyz="0 0 0"/>
    <parent link="victor_right_arm_mount"/>
    <child link="victor_right_arm_link_0"/>
  </joint>
  <link name="victor_right_arm_link_0">
    <inertial>
      <origin rpy="0 0 0" xyz="-0.1 0 0.07"/>
      <mass value="5"/>
      <inertia ixx="0.05" ixy="0" ixz="0" iyy="0.06" iyz="0" izz="0.03"/>
    </inertial>
    <visual>
      <origin rpy="0 0 0" xyz="0 0 0"/>
      <geometry>
        <mesh filename="package://victor_description/meshes/iiwa7/visual/link_0.stl"/>
      </geometry>
      <material name="Grey"/>
    </visual>
    <collision>
      <origin rpy="0 0 0" xyz="0 0 0"/>
      <geometry>
        <mesh filename="package://victor_description/meshes/iiwa7/collision/link_0.stl"/>
      </geometry>
      <material name="Grey"/>
    </collision>
    <self_collision_checking>
      <origin rpy="0 0 0" xyz="0 0 0"/>
      <geometry>
        <capsule length="0.25" radius="0.15"/>
      </geometry>
    </self_collision_checking>
  </link>
  <!-- joint between link_0 and link_1 -->
  <joint name="victor_right_arm_joint_1" type="revolute">
    <parent link="victor_right_arm_link_0"/>
    <child link="victor_right_arm_link_1"/>
    <origin rpy="0 0 0" xyz="0 0 0.15"/>
    <axis xyz="0 0 1"/>
    <limit effort="300" lower="-2.96705972839" upper="2.96705972839" velocity="10"/>
    <safety_controller k_position="100" k_velocity="2" soft_lower_limit="-2.93215314335" soft_upper_limit="2.93215314335"/>
    <dynamics damping="0.5"/>
  </joint>
  <link name="victor_right_arm_link_1">
    <inertial>
      <origin rpy="0 0 0" xyz="0 -0.03 0.12"/>
      <mass value="3.4525"/>
      <inertia ixx="0.02183" ixy="0" ixz="0" iyy="0.007703" iyz="-0.003887" izz="0.02083"/>
    </inertial>
    <visual>
      <origin rpy="0 0 0" xyz="0 0 0.0075"/>
      <geometry>
        <mesh filename="package://victor_description/meshes/iiwa7/visual/link_1.stl"/>
      </geometry>
      <material name="Orange"/>
    </visual>
    <collision>
      <origin rpy="0 0 0" xyz="0 0 0.0075"/>
      <geometry>
        <mesh filename="package://victor_description/meshes/iiwa7/collision/link_1.stl"/>
      </geometry>
      <material name="Orange"/>
    </collision>
  </link>
  <joint name="victor_right_arm_joint_2" type="revolute">
    <parent link="victor_right_arm_link_1"/>
    <child link="victor_right_arm_link_2"/>
    <origin rpy="1.57079632679   0 3.14159265359" xyz="0 0 0.19"/>
    <axis xyz="0 0 1"/>
    <limit effort="300" lower="-2.09439510239" upper="2.09439510239" velocity="10"/>
    <safety_controller k_position="100" k_velocity="2" soft_lower_limit="-2.05948851735" soft_upper_limit="2.05948851735"/>
    <dynamics damping="0.5"/>
  </joint>
  <link name="victor_right_arm_link_2">
    <inertial>
      <origin rpy="0 0 0" xyz="0.0003 0.059 0.042"/>
      <mass value="3.4821"/>
      <inertia ixx="0.02076" ixy="0" ixz="-0.003626" iyy="0.02179" iyz="0" izz="0.00779"/>
    </inertial>
    <visual>
      <origin rpy="0 0 0" xyz="0 0 0"/>
      <geometry>
        <mesh filename="package://victor_description/meshes/iiwa7/visual/link_2.stl"/>
      </geometry>
      <material name="Orange"/>
    </visual>
    <collision>
      <origin rpy="0 0 0" xyz="0 0 0"/>
      <geometry>
        <mesh filename="package://victor_description/meshes/iiwa7/collision/link_2.stl"/>
      </geometry>
      <material name="Orange"/>
    </collision>
  </link>
  <joint name="victor_right_arm_joint_3" type="revolute">
    <parent link="victor_right_arm_link_2"/>
    <child link="victor_right_arm_link_3"/>
    <origin rpy="1.57079632679 0 3.14159265359" xyz="0 0.21 0"/>
    <axis xyz="0 0 1"/>
    <limit effort="300" lower="-2.96705972839" upper="2.96705972839" velocity="10"/>
    <safety_controller k_position="100" k_velocity="2" soft_lower_limit="-2.93215314335" soft_upper_limit="2.93215314335"/>
    <dynamics damping="0.5"/>
  </joint>
  <link name="victor_right_arm_link_3">
    <inertial>
      <origin rpy="0 0 0" xyz="0 0.03 0.13"/>
      <mass value="4.05623"/>
      <inertia ixx="0.03204" ixy="0" ixz="0" iyy="0.00972" iyz="0.006227" izz="0.03042"/>
    </inertial>
    <visual>
      <origin rpy="0 0 0" xyz="0 0 -0.026"/>
      <geometry>
        <mesh filename="package://victor_description/meshes/iiwa7/visual/link_3.stl"/>
      </geometry>
      <material name="Orange"/>
    </visual>
    <collision>
      <origin rpy="0 0 0" xyz="0 0 -0.026"/>
      <geometry>
        <mesh filename="package://victor_description/meshes/iiwa7/collision/link_3.stl"/>
      </geometry>
      <material name="Orange"/>
    </collision>
  </link>
  <joint name="victor_right_arm_joint_4" type="revolute">
    <parent link="victor_right_arm_link_3"/>
    <child link="victor_right_arm_link_4"/>
    <origin rpy="1.57079632679 0 0" xyz="0 0 0.19"/>
    <axis xyz="0 0 1"/>
    <limit effort="300" lower="-2.09439510239" upper="2.09439510239" velocity="10"/>
    <safety_controller k_position="100" k_velocity="2" soft_lower_limit="-2.05948851735" soft_upper_limit="2.05948851735"/>
    <dynamics damping="0.5"/>
  </joint>
  <link name="victor_right_arm_link_4">
    <inertial>
      <origin rpy="0 0 0" xyz="0 0.067 0.034"/>
      <mass value="3.4822"/>
      <inertia ixx="0.02178" ixy="0" ixz="0" iyy="0.02075" iyz="-0.003625" izz="0.007785"/>
    </inertial>
    <visual>
      <origin rpy="0 0 0" xyz="0 0 0"/>
      <geometry>
        <mesh filename="package://victor_description/meshes/iiwa7/visual/link_4.stl"/>
      </geometry>
      <material name="Orange"/>
    </visual>
    <collision>
      <origin rpy="0 0 0" xyz="0 0 0"/>
      <geometry>
        <mesh filename="package://victor_description/meshes/iiwa7/collision/link_4.stl"/>
      </geometry>
      <material name="Orange"/>
    </collision>
  </link>
  <joint name="victor_right_arm_joint_5" type="revolute">
    <parent link="victor_right_arm_link_4"/>
    <child link="victor_right_arm_link_5"/>
    <origin rpy="-1.57079632679 3.14159265359 0" xyz="0 0.21 0"/>
    <axis xyz="0 0 1"/>
    <limit effort="300" lower="-2.96705972839" upper="2.96705972839" velocity="10"/>
    <safety_controller k_position="100" k_velocity="2" soft_lower_limit="-2.93215314335" soft_upper_limit="2.93215314335"/>
    <dynamics damping="0.5"/>
  </joint>
  <link name="victor_right_arm_link_5">
    <inertial>
      <origin rpy="0 0 0" xyz="0.0001 0.021 0.076"/>
      <mass value="2.1633"/>
      <inertia ixx="0.01287" ixy="0" ixz="0" iyy="0.005708" iyz="-0.003946" izz="0.01112"/>
    </inertial>
    <visual>
      <origin rpy="0 0 0" xyz="0 0 -0.026"/>
      <geometry>
        <mesh filename="package://victor_description/meshes/iiwa7/visual/link_5.stl"/>
      </geometry>
      <material name="Orange"/>
    </visual>
    <collision>
      <origin rpy="0 0 0" xyz="0 0 -0.026"/>
      <geometry>
        <mesh filename="package://victor_description/meshes/iiwa7/collision/link_5.stl"/>
      </geometry>
      <material name="Orange"/>
    </collision>
  </link>
  <joint name="victor_right_arm_joint_6" type="revolute">
    <parent link="victor_right_arm_link_5"/>
    <child link="victor_right_arm_link_6"/>
    <origin rpy="1.57079632679 0 0" xyz="0 0.06070 0.19"/>
    <axis xyz="0 0 1"/>
    <limit effort="300" lower="-2.09439510239" upper="2.09439510239" velocity="10"/>
    <safety_controller k_position="100" k_velocity="2" soft_lower_limit="-2.05948851735" soft_upper_limit="2.05948851735"/>
    <dynamics damping="0.5"/>
  </joint>
  <link name="victor_right_arm_link_6">
    <inertial>
      <origin rpy="0 0 0" xyz="0 0.0006 0.0004"/>
      <mass value="2.3466"/>
      <inertia ixx="0.006509" ixy="0" ixz="0" iyy="0.006259" iyz="0.00031891" izz="0.004527"/>
    </inertial>
    <visual>
      <origin rpy="0 0 0" xyz="0 0 0"/>
      <geometry>
        <mesh filename="package://victor_description/meshes/iiwa7/visual/link_6.stl"/>
      </geometry>
      <material name="Orange"/>
    </visual>
    <collision>
      <origin rpy="0 0 0" xyz="0 0 0"/>
      <geometry>
        <mesh filename="package://victor_description/meshes/iiwa7/collision/link_6.stl"/>
      </geometry>
      <material name="Orange"/>
    </collision>
  </link>
  <joint name="victor_right_arm_joint_7" type="revolute">
    <parent link="victor_right_arm_link_6"/>
    <child link="victor_right_arm_link_7"/>
    <origin rpy="-1.57079632679 3.14159265359 0" xyz="0 0.081 0.06070"/>
    <axis xyz="0 0 1"/>
    <limit effort="300" lower="-3.05432619099" upper="3.05432619099" velocity="10"/>
    <safety_controller k_position="100" k_velocity="2" soft_lower_limit="-3.01941960595" soft_upper_limit="3.01941960595"/>
    <dynamics damping="0.5"/>
  </joint>
  <link name="victor_right_arm_link_7">
    <inertial>
      <origin rpy="0 0 0" xyz="0 0 0.02"/>
      <mass value="3.129"/>
      <inertia ixx="0.01464" ixy="0.0005912" ixz="0" iyy="0.01465" iyz="0" izz="0.002872"/>
    </inertial>
    <visual>
      <origin rpy="0 0 0" xyz="0 0 -0.0005"/>
      <geometry>
        <mesh filename="package://victor_description/meshes/iiwa7/visual/link_7_electric.stl"/>
      </geometry>
      <material name="Grey"/>
    </visual>
    <collision>
      <origin rpy="0 0 0" xyz="0 0 -0.0005"/>
      <geometry>
        <mesh filename="package://victor_description/meshes/iiwa7/collision/link_7_electric.stl"/>
      </geometry>
      <material name="Grey"/>
    </collision>
  </link>
  <joint name="victor_right_arm_joint_flange" type="fixed">
    <parent link="victor_right_arm_link_7"/>
    <child link="victor_right_arm_flange"/>
    <origin rpy="0 0 0" xyz="0 0 0.045"/>
  </joint>
  <link name="victor_right_arm_flange">
        </link>
  <!-- Our usage above has been tweaked to match Kuka's internal usage, so identity transform -->
  <joint name="victor_right_arm_flange_kuka_joint" type="fixed">
    <parent link="victor_right_arm_flange"/>
    <child link="victor_right_arm_flange_kuka"/>
    <origin rpy="0 0 0" xyz="0 0 0"/>
  </joint>
  <link name="victor_right_arm_flange_kuka">
        </link>
  <!-- Load Gazebo lib and set the robot namespace -->
  <gazebo>
    <plugin filename="libgazebo_ros_control.so" name="gazebo_ros_control">
      <robotNamespace>/victor_right_arm</robotNamespace>
    </plugin>
  </gazebo>
  <!-- Link0 -->
  <gazebo reference="iiwa_link_0">
    <material>Gazebo/Grey</material>
    <mu1>0.2</mu1>
    <mu2>0.2</mu2>
  </gazebo>
  <!-- Link1 -->
  <gazebo reference="iiwa_link_1">
    <material>Gazebo/Orange</material>
    <mu1>0.2</mu1>
    <mu2>0.2</mu2>
  </gazebo>
  <!-- Link2 -->
  <gazebo reference="iiwa_link_2">
    <material>Gazebo/Orange</material>
    <mu1>0.2</mu1>
    <mu2>0.2</mu2>
  </gazebo>
  <!-- Link3 -->
  <gazebo reference="iiwa_link_3">
    <material>Gazebo/Orange</material>
    <mu1>0.2</mu1>
    <mu2>0.2</mu2>
  </gazebo>
  <!-- Link4 -->
  <gazebo reference="iiwa_link_4">
    <material>Gazebo/Orange</material>
    <mu1>0.2</mu1>
    <mu2>0.2</mu2>
  </gazebo>
  <!-- Link5 -->
  <gazebo reference="iiwa_link_5">
    <material>Gazebo/Orange</material>
    <mu1>0.2</mu1>
    <mu2>0.2</mu2>
  </gazebo>
  <!-- Link6 -->
  <gazebo reference="iiwa_link_6">
    <material>Gazebo/Orange</material>
    <mu1>0.2</mu1>
    <mu2>0.2</mu2>
  </gazebo>
  <!-- Link7 -->
  <gazebo reference="iiwa_link_7">
    <material>Gazebo/Grey</material>
    <mu1>0.2</mu1>
    <mu2>0.2</mu2>
  </gazebo>
  <transmission name="iiwa_tran_1">
    <robotNamespace>/victor_right_arm</robotNamespace>
    <type>transmission_interface/SimpleTransmission</type>
    <joint name="iiwa_joint_1">
      <hardwareInterface>PositionJointInterface</hardwareInterface>
    </joint>
    <actuator name="iiwa_motor_1">
      <hardwareInterface>PositionJointInterface</hardwareInterface>
      <mechanicalReduction>1</mechanicalReduction>
    </actuator>
  </transmission>
  <transmission name="iiwa_tran_2">
    <robotNamespace>/victor_right_arm</robotNamespace>
    <type>transmission_interface/SimpleTransmission</type>
    <joint name="iiwa_joint_2">
      <hardwareInterface>PositionJointInterface</hardwareInterface>
    </joint>
    <actuator name="iiwa_motor_2">
      <hardwareInterface>PositionJointInterface</hardwareInterface>
      <mechanicalReduction>1</mechanicalReduction>
    </actuator>
  </transmission>
  <transmission name="iiwa_tran_3">
    <robotNamespace>/victor_right_arm</robotNamespace>
    <type>transmission_interface/SimpleTransmission</type>
    <joint name="iiwa_joint_3">
      <hardwareInterface>PositionJointInterface</hardwareInterface>
    </joint>
    <actuator name="iiwa_motor_3">
      <hardwareInterface>PositionJointInterface</hardwareInterface>
      <mechanicalReduction>1</mechanicalReduction>
    </actuator>
  </transmission>
  <transmission name="iiwa_tran_4">
    <robotNamespace>/victor_right_arm</robotNamespace>
    <type>transmission_interface/SimpleTransmission</type>
    <joint name="iiwa_joint_4">
      <hardwareInterface>PositionJointInterface</hardwareInterface>
    </joint>
    <actuator name="iiwa_motor_4">
      <hardwareInterface>PositionJointInterface</hardwareInterface>
      <mechanicalReduction>1</mechanicalReduction>
    </actuator>
  </transmission>
  <transmission name="iiwa_tran_5">
    <robotNamespace>/victor_right_arm</robotNamespace>
    <type>transmission_interface/SimpleTransmission</type>
    <joint name="iiwa_joint_5">
      <hardwareInterface>PositionJointInterface</hardwareInterface>
    </joint>
    <actuator name="iiwa_motor_5">
      <hardwareInterface>PositionJointInterface</hardwareInterface>
      <mechanicalReduction>1</mechanicalReduction>
    </actuator>
  </transmission>
  <transmission name="iiwa_tran_6">
    <robotNamespace>/victor_right_arm</robotNamespace>
    <type>transmission_interface/SimpleTransmission</type>
    <joint name="iiwa_joint_6">
      <hardwareInterface>PositionJointInterface</hardwareInterface>
    </joint>
    <actuator name="iiwa_motor_6">
      <hardwareInterface>PositionJointInterface</hardwareInterface>
      <mechanicalReduction>1</mechanicalReduction>
    </actuator>
  </transmission>
  <transmission name="iiwa_tran_7">
    <robotNamespace>/victor_right_arm</robotNamespace>
    <type>transmission_interface/SimpleTransmission</type>
    <joint name="iiwa_joint_7">
      <hardwareInterface>PositionJointInterface</hardwareInterface>
    </joint>
    <actuator name="iiwa_motor_7">
      <hardwareInterface>PositionJointInterface</hardwareInterface>
      <mechanicalReduction>1</mechanicalReduction>
    </actuator>
  </transmission>
  <joint name="victor_joint_right_arm_world_frame_kuka" type="fixed">
    <parent link="victor_right_arm_mount"/>
    <child link="victor_right_arm_world_frame_kuka"/>
    <origin rpy="-1.57079632679 0 0" xyz="0 0 0"/>
  </joint>
  <link name="victor_right_arm_world_frame_kuka">
    </link>
  <!--joint between {parent} and link_0-->
  <joint name="victor_left_arm_flange_victor_left_joint" type="fixed">
    <origin rpy="0 0 0" xyz="0 0 0"/>
    <parent link="victor_left_arm_flange"/>
    <child link="victor_left_gripper_mounting_bracket"/>
  </joint>
  <link name="victor_left_gripper_mounting_bracket">
    <visual>
      <origin rpy="0 0 0" xyz="0 0 0"/>
      <geometry>
        <mesh filename="package://victor_description/meshes/robotiq_3finger/kuka_to_palm_connectors_visual.stl"/>
      </geometry>
      <material name="LightGrey"/>
    </visual>
    <collision>
      <origin rpy="0 0 0" xyz="0 0 0"/>
      <geometry>
        <mesh filename="package://victor_description/meshes/robotiq_3finger/kuka_to_palm_connectors_collision.stl"/>
      </geometry>
      <material name="LightGrey"/>
    </collision>
  </link>
  <!--joint between {parent} and link_0-->
  <joint name="victor_right_arm_flange_victor_right_joint" type="fixed">
    <origin rpy="0 0 0" xyz="0 0 0"/>
    <parent link="victor_right_arm_flange"/>
    <child link="victor_right_gripper_mounting_bracket"/>
  </joint>
  <link name="victor_right_gripper_mounting_bracket">
    <visual>
      <origin rpy="0 0 0" xyz="0 0 0"/>
      <geometry>
        <mesh filename="package://victor_description/meshes/robotiq_3finger/kuka_to_palm_connectors_visual.stl"/>
      </geometry>
      <material name="LightGrey"/>
    </visual>
    <collision>
      <origin rpy="0 0 0" xyz="0 0 0"/>
      <geometry>
        <mesh filename="package://victor_description/meshes/robotiq_3finger/kuka_to_palm_connectors_collision.stl"/>
      </geometry>
      <material name="LightGrey"/>
    </collision>
  </link>
  <joint name="victor_left_gripper_palm_joint" type="fixed">
    <origin rpy="0 0 0.785398163397" xyz="0 0 0.02705"/>
    <parent link="victor_left_gripper_mounting_bracket"/>
    <child link="victor_left_gripper_palm"/>
  </joint>
  <link name="victor_left_gripper_palm">
    <inertial>
      <origin rpy="0 0 0" xyz="0 0 0"/>
      <mass value="1"/>
      <inertia ixx="0.01" ixy="0" ixz="0" iyy="0.01" iyz="0" izz="0.01"/>
    </inertial>
    <visual>
      <origin rpy="0 0 0" xyz="0 0 0"/>
      <geometry>
        <mesh filename="package://victor_description/meshes/robotiq_3finger/palm_visual.stl"/>
      </geometry>
      <material name="DarkGray"/>
    </visual>
    <collision>
      <origin rpy="0 0 0" xyz="0 0 0"/>
      <geometry>
        <mesh filename="package://victor_description/meshes/robotiq_3finger/palm_collision.stl"/>
      </geometry>
      <material name="DarkGray"/>
    </collision>
  </link>
  <!-- Palm surface aligned with the gripper axis -->
  <joint name="victor_left_gripper_palm_surface_joint" type="fixed">
    <parent link="victor_left_gripper_palm"/>
    <child link="victor_left_gripper_palm_surface"/>
    <origin rpy="0 0 0" xyz="0 0 0.092075"/>
  </joint>
  <link name="victor_left_gripper_palm_surface">
        </link>
  <!-- Kuka internal frame has been changed to match our external usage, so identity transform -->
  <joint name="victor_left_gripper_palm_surface_kuka_joint" type="fixed">
    <parent link="victor_left_gripper_palm_surface"/>
    <child link="victor_left_gripper_palm_surface_kuka"/>
    <origin rpy="0 0 0" xyz="0 0 0"/>
  </joint>
  <link name="victor_left_gripper_palm_surface_kuka">
        </link>
  <!-- Finger A -->
  <joint name="victor_left_gripper_fingerA_knuckle" type="fixed">
    <origin rpy="0 0 0" xyz="0.02225040 0 0.06111875"/>
    <parent link="victor_left_gripper_palm"/>
    <child link="victor_left_gripper_fingerA_base"/>
  </joint>
  <link name="victor_left_gripper_fingerA_base">
    <inertial>
      <origin rpy="0 0 0" xyz="0 0 0"/>
      <mass value="1"/>
      <inertia ixx="0.01" ixy="0" ixz="0" iyy="0.01" iyz="0" izz="0.01"/>
    </inertial>
    <visual>
      <origin rpy="0 0 0" xyz="0 0 0"/>
      <geometry>
        <mesh filename="package://victor_description/meshes/robotiq_3finger/finger_link1_base_visual.stl"/>
      </geometry>
      <material name="DarkGray"/>
    </visual>
    <collision>
      <origin rpy="0 0 0" xyz="0 0 0"/>
      <geometry>
        <mesh filename="package://victor_description/meshes/robotiq_3finger/finger_link1_base_visual.stl"/>
      </geometry>
      <material name="DarkGray"/>
    </collision>
  </link>
  <!-- Joint 2 (base-prox) -->
  <joint name="victor_left_gripper_fingerA_joint_2" type="revolute">
    <parent link="victor_left_gripper_fingerA_base"/>
    <child link="victor_left_gripper_fingerA_prox"/>
    <origin rpy="0 0.610865238198 0" xyz="0.02225000 0 0.02151380"/>
    <axis xyz="0 -1 0"/>
    <limit effort="300" lower="0" upper="1.2217304763960307" velocity="10"/>
    <safety_controller k_position="100" k_velocity="2" soft_lower_limit="-0.610865238198" soft_upper_limit="0.610865238198"/>
    <dynamics damping="0.5"/>
  </joint>
  <link name="victor_left_gripper_fingerA_prox">
    <inertial>
      <origin rpy="0 0 0" xyz="0 0 0"/>
      <mass value="1"/>
      <inertia ixx="0.01" ixy="0" ixz="0" iyy="0.01" iyz="0" izz="0.01"/>
    </inertial>
    <visual>
      <origin rpy="0 0 0" xyz="0 0 0"/>
      <geometry>
        <mesh filename="package://victor_description/meshes/robotiq_3finger/finger_link2_prox_visual.stl"/>
      </geometry>
      <material name="DarkGray"/>
    </visual>
    <collision>
      <origin rpy="0 0 0" xyz="0 0 0"/>
      <geometry>
        <mesh filename="package://victor_description/meshes/robotiq_3finger/finger_link2_prox_collision.stl"/>
      </geometry>
      <material name="DarkGray"/>
    </collision>
  </link>
  <!-- Joint 3 (prox-med) -->
  <joint name="victor_left_gripper_fingerA_joint_3" type="revolute">
    <parent link="victor_left_gripper_fingerA_prox"/>
    <child link="victor_left_gripper_fingerA_med"/>
    <origin rpy="0 0 0" xyz="0 0 0.05715000"/>
    <axis xyz="0 -1 0"/>
    <limit effort="300" lower="-1" upper="1" velocity="10"/>
    <safety_controller k_position="100" k_velocity="2" soft_lower_limit="0.0" soft_upper_limit="1.57079632679"/>
    <dynamics damping="0.5"/>
  </joint>
  <link name="victor_left_gripper_fingerA_med">
    <inertial>
      <origin rpy="0 0 0" xyz="0 0 0"/>
      <mass value="1"/>
      <inertia ixx="0.01" ixy="0" ixz="0" iyy="0.01" iyz="0" izz="0.01"/>
    </inertial>
    <visual>
      <origin rpy="0 0 0" xyz="0 0 0"/>
      <geometry>
        <mesh filename="package://victor_description/meshes/robotiq_3finger/finger_link3_med_visual.stl"/>
      </geometry>
      <material name="DarkGray"/>
    </visual>
    <collision>
      <origin rpy="0 0 0" xyz="0 0 0"/>
      <geometry>
        <mesh filename="package://victor_description/meshes/robotiq_3finger/finger_link3_med_collision.stl"/>
      </geometry>
      <material name="DarkGray"/>
    </collision>
  </link>
  <!-- Joint 4 (med-dist) -->
  <joint name="victor_left_gripper_fingerA_joint_4" type="revolute">
    <parent link="victor_left_gripper_fingerA_med"/>
    <child link="victor_left_gripper_fingerA_dist"/>
    <origin rpy="0 -0.436332312999 0" xyz="0 0 0.03810000"/>
    <axis xyz="0 -1 0"/>
    <limit effort="300" lower="-1" upper="1" velocity="10"/>
    <safety_controller k_position="100" k_velocity="2" soft_lower_limit="-0.436332312999" soft_upper_limit="1.27409035396"/>
    <dynamics damping="0.5"/>
  </joint>
  <link name="victor_left_gripper_fingerA_dist">
    <inertial>
      <origin rpy="0 0 0" xyz="0 0 0"/>
      <mass value="1"/>
      <inertia ixx="0.01" ixy="0" ixz="0" iyy="0.01" iyz="0" izz="0.01"/>
    </inertial>
    <visual>
      <origin rpy="0 0 0" xyz="0 0 0"/>
      <geometry>
        <mesh filename="package://victor_description/meshes/robotiq_3finger/finger_link4_dist_visual.stl"/>
      </geometry>
      <material name="DarkGray"/>
    </visual>
    <collision>
      <origin rpy="0 0 0" xyz="0 0 0"/>
      <geometry>
        <mesh filename="package://victor_description/meshes/robotiq_3finger/finger_link4_dist_collision.stl"/>
      </geometry>
      <material name="DarkGray"/>
    </collision>
  </link>
  <!-- Finger B -->
  <joint name="victor_left_gripper_fingerB_knuckle" type="revolute">
    <origin rpy="0 0 3.14159265359" xyz="-0.02230120 0.03651250 0.06111875"/>
    <parent link="victor_left_gripper_palm"/>
    <child link="victor_left_gripper_fingerB_base"/>
    <axis xyz="-1 0 0"/>
    <limit effort="300" lower="-0.279252680319" upper="0.174532925199" velocity="10"/>
    <safety_controller k_position="100" k_velocity="2" soft_lower_limit="-0.244346095279" soft_upper_limit="0.13962634016"/>
    <dynamics damping="0.5"/>
  </joint>
  <link name="victor_left_gripper_fingerB_base">
    <inertial>
      <origin rpy="0 0 0" xyz="0 0 0"/>
      <mass value="1"/>
      <inertia ixx="0.01" ixy="0" ixz="0" iyy="0.01" iyz="0" izz="0.01"/>
    </inertial>
    <visual>
      <origin rpy="0 0 0" xyz="0 0 0"/>
      <geometry>
        <mesh filename="package://victor_description/meshes/robotiq_3finger/finger_link1_base_visual.stl"/>
      </geometry>
      <material name="DarkGray"/>
    </visual>
    <collision>
      <origin rpy="0 0 0" xyz="0 0 0"/>
      <geometry>
        <mesh filename="package://victor_description/meshes/robotiq_3finger/finger_link1_base_visual.stl"/>
      </geometry>
      <material name="DarkGray"/>
    </collision>
  </link>
  <!-- Joint 2 (base-prox) -->
  <joint name="victor_left_gripper_fingerB_joint_2" type="revolute">
    <parent link="victor_left_gripper_fingerB_base"/>
    <child link="victor_left_gripper_fingerB_prox"/>
    <origin rpy="0 0.610865238198 0" xyz="0.02225000 0 0.02151380"/>
    <axis xyz="0 -1 0"/>
    <limit effort="300" lower="0" upper="1.2217304763960307" velocity="10"/>
    <safety_controller k_position="100" k_velocity="2" soft_lower_limit="-0.610865238198" soft_upper_limit="0.610865238198"/>
    <dynamics damping="0.5"/>
  </joint>
  <link name="victor_left_gripper_fingerB_prox">
    <inertial>
      <origin rpy="0 0 0" xyz="0 0 0"/>
      <mass value="1"/>
      <inertia ixx="0.01" ixy="0" ixz="0" iyy="0.01" iyz="0" izz="0.01"/>
    </inertial>
    <visual>
      <origin rpy="0 0 0" xyz="0 0 0"/>
      <geometry>
        <mesh filename="package://victor_description/meshes/robotiq_3finger/finger_link2_prox_visual.stl"/>
      </geometry>
      <material name="DarkGray"/>
    </visual>
    <collision>
      <origin rpy="0 0 0" xyz="0 0 0"/>
      <geometry>
        <mesh filename="package://victor_description/meshes/robotiq_3finger/finger_link2_prox_collision.stl"/>
      </geometry>
      <material name="DarkGray"/>
    </collision>
  </link>
  <!-- Joint 3 (prox-med) -->
  <joint name="victor_left_gripper_fingerB_joint_3" type="revolute">
    <parent link="victor_left_gripper_fingerB_prox"/>
    <child link="victor_left_gripper_fingerB_med"/>
    <origin rpy="0 0 0" xyz="0 0 0.05715000"/>
    <axis xyz="0 -1 0"/>
    <limit effort="300" lower="-1" upper="1" velocity="10"/>
    <safety_controller k_position="100" k_velocity="2" soft_lower_limit="0.0" soft_upper_limit="1.57079632679"/>
    <dynamics damping="0.5"/>
  </joint>
  <link name="victor_left_gripper_fingerB_med">
    <inertial>
      <origin rpy="0 0 0" xyz="0 0 0"/>
      <mass value="1"/>
      <inertia ixx="0.01" ixy="0" ixz="0" iyy="0.01" iyz="0" izz="0.01"/>
    </inertial>
    <visual>
      <origin rpy="0 0 0" xyz="0 0 0"/>
      <geometry>
        <mesh filename="package://victor_description/meshes/robotiq_3finger/finger_link3_med_visual.stl"/>
      </geometry>
      <material name="DarkGray"/>
    </visual>
    <collision>
      <origin rpy="0 0 0" xyz="0 0 0"/>
      <geometry>
        <mesh filename="package://victor_description/meshes/robotiq_3finger/finger_link3_med_collision.stl"/>
      </geometry>
      <material name="DarkGray"/>
    </collision>
  </link>
  <!-- Joint 4 (med-dist) -->
  <joint name="victor_left_gripper_fingerB_joint_4" type="revolute">
    <parent link="victor_left_gripper_fingerB_med"/>
    <child link="victor_left_gripper_fingerB_dist"/>
    <origin rpy="0 -0.436332312999 0" xyz="0 0 0.03810000"/>
    <axis xyz="0 -1 0"/>
    <limit effort="300" lower="-1" upper="1" velocity="10"/>
    <safety_controller k_position="100" k_velocity="2" soft_lower_limit="-0.436332312999" soft_upper_limit="1.27409035396"/>
    <dynamics damping="0.5"/>
  </joint>
  <link name="victor_left_gripper_fingerB_dist">
    <inertial>
      <origin rpy="0 0 0" xyz="0 0 0"/>
      <mass value="1"/>
      <inertia ixx="0.01" ixy="0" ixz="0" iyy="0.01" iyz="0" izz="0.01"/>
    </inertial>
    <visual>
      <origin rpy="0 0 0" xyz="0 0 0"/>
      <geometry>
        <mesh filename="package://victor_description/meshes/robotiq_3finger/finger_link4_dist_visual.stl"/>
      </geometry>
      <material name="DarkGray"/>
    </visual>
    <collision>
      <origin rpy="0 0 0" xyz="0 0 0"/>
      <geometry>
        <mesh filename="package://victor_description/meshes/robotiq_3finger/finger_link4_dist_collision.stl"/>
      </geometry>
      <material name="DarkGray"/>
    </collision>
  </link>
  <!-- Finger C -->
  <joint name="victor_left_gripper_fingerC_knuckle" type="revolute">
    <origin rpy="0 0 3.14159265359" xyz="-0.02230120 -0.03651250 0.06111875"/>
    <parent link="victor_left_gripper_palm"/>
    <child link="victor_left_gripper_fingerC_base"/>
    <axis xyz="1 0 0"/>
    <limit effort="300" lower="-0.279252680319" upper="0.174532925199" velocity="10"/>
    <safety_controller k_position="100" k_velocity="2" soft_lower_limit="-0.244346095279" soft_upper_limit="0.13962634016"/>
    <dynamics damping="0.5"/>
  </joint>
  <link name="victor_left_gripper_fingerC_base">
    <inertial>
      <origin rpy="0 0 0" xyz="0 0 0"/>
      <mass value="1"/>
      <inertia ixx="0.01" ixy="0" ixz="0" iyy="0.01" iyz="0" izz="0.01"/>
    </inertial>
    <visual>
      <origin rpy="0 0 0" xyz="0 0 0"/>
      <geometry>
        <mesh filename="package://victor_description/meshes/robotiq_3finger/finger_link1_base_visual.stl"/>
      </geometry>
      <material name="DarkGray"/>
    </visual>
    <collision>
      <origin rpy="0 0 0" xyz="0 0 0"/>
      <geometry>
        <mesh filename="package://victor_description/meshes/robotiq_3finger/finger_link1_base_visual.stl"/>
      </geometry>
      <material name="DarkGray"/>
    </collision>
  </link>
  <!-- Joint 2 (base-prox) -->
  <joint name="victor_left_gripper_fingerC_joint_2" type="revolute">
    <parent link="victor_left_gripper_fingerC_base"/>
    <child link="victor_left_gripper_fingerC_prox"/>
    <origin rpy="0 0.610865238198 0" xyz="0.02225000 0 0.02151380"/>
    <axis xyz="0 -1 0"/>
    <limit effort="300" lower="0" upper="1.2217304763960307" velocity="10"/>
    <safety_controller k_position="100" k_velocity="2" soft_lower_limit="-0.610865238198" soft_upper_limit="0.610865238198"/>
    <dynamics damping="0.5"/>
  </joint>
  <link name="victor_left_gripper_fingerC_prox">
    <inertial>
      <origin rpy="0 0 0" xyz="0 0 0"/>
      <mass value="1"/>
      <inertia ixx="0.01" ixy="0" ixz="0" iyy="0.01" iyz="0" izz="0.01"/>
    </inertial>
    <visual>
      <origin rpy="0 0 0" xyz="0 0 0"/>
      <geometry>
        <mesh filename="package://victor_description/meshes/robotiq_3finger/finger_link2_prox_visual.stl"/>
      </geometry>
      <material name="DarkGray"/>
    </visual>
    <collision>
      <origin rpy="0 0 0" xyz="0 0 0"/>
      <geometry>
        <mesh filename="package://victor_description/meshes/robotiq_3finger/finger_link2_prox_collision.stl"/>
      </geometry>
      <material name="DarkGray"/>
    </collision>
  </link>
  <!-- Joint 3 (prox-med) -->
  <joint name="victor_left_gripper_fingerC_joint_3" type="revolute">
    <parent link="victor_left_gripper_fingerC_prox"/>
    <child link="victor_left_gripper_fingerC_med"/>
    <origin rpy="0 0 0" xyz="0 0 0.05715000"/>
    <axis xyz="0 -1 0"/>
    <limit effort="300" lower="-1" upper="1" velocity="10"/>
    <safety_controller k_position="100" k_velocity="2" soft_lower_limit="0.0" soft_upper_limit="1.57079632679"/>
    <dynamics damping="0.5"/>
  </joint>
  <link name="victor_left_gripper_fingerC_med">
    <inertial>
      <origin rpy="0 0 0" xyz="0 0 0"/>
      <mass value="1"/>
      <inertia ixx="0.01" ixy="0" ixz="0" iyy="0.01" iyz="0" izz="0.01"/>
    </inertial>
    <visual>
      <origin rpy="0 0 0" xyz="0 0 0"/>
      <geometry>
        <mesh filename="package://victor_description/meshes/robotiq_3finger/finger_link3_med_visual.stl"/>
      </geometry>
      <material name="DarkGray"/>
    </visual>
    <collision>
      <origin rpy="0 0 0" xyz="0 0 0"/>
      <geometry>
        <mesh filename="package://victor_description/meshes/robotiq_3finger/finger_link3_med_collision.stl"/>
      </geometry>
      <material name="DarkGray"/>
    </collision>
  </link>
  <!-- Joint 4 (med-dist) -->
  <joint name="victor_left_gripper_fingerC_joint_4" type="revolute">
    <parent link="victor_left_gripper_fingerC_med"/>
    <child link="victor_left_gripper_fingerC_dist"/>
    <origin rpy="0 -0.436332312999 0" xyz="0 0 0.03810000"/>
    <axis xyz="0 -1 0"/>
    <limit effort="300" lower="-1" upper="1" velocity="10"/>
    <safety_controller k_position="100" k_velocity="2" soft_lower_limit="-0.436332312999" soft_upper_limit="1.27409035396"/>
    <dynamics damping="0.5"/>
  </joint>
  <link name="victor_left_gripper_fingerC_dist">
    <inertial>
      <origin rpy="0 0 0" xyz="0 0 0"/>
      <mass value="1"/>
      <inertia ixx="0.01" ixy="0" ixz="0" iyy="0.01" iyz="0" izz="0.01"/>
    </inertial>
    <visual>
      <origin rpy="0 0 0" xyz="0 0 0"/>
      <geometry>
        <mesh filename="package://victor_description/meshes/robotiq_3finger/finger_link4_dist_visual.stl"/>
      </geometry>
      <material name="DarkGray"/>
    </visual>
    <collision>
      <origin rpy="0 0 0" xyz="0 0 0"/>
      <geometry>
        <mesh filename="package://victor_description/meshes/robotiq_3finger/finger_link4_dist_collision.stl"/>
      </geometry>
      <material name="DarkGray"/>
    </collision>
  </link>
  <joint name="victor_right_gripper_palm_joint" type="fixed">
    <origin rpy="0 0 0.785398163397" xyz="0 0 0.02705"/>
    <parent link="victor_right_gripper_mounting_bracket"/>
    <child link="victor_right_gripper_palm"/>
  </joint>
  <link name="victor_right_gripper_palm">
    <inertial>
      <origin rpy="0 0 0" xyz="0 0 0"/>
      <mass value="1"/>
      <inertia ixx="0.01" ixy="0" ixz="0" iyy="0.01" iyz="0" izz="0.01"/>
    </inertial>
    <visual>
      <origin rpy="0 0 0" xyz="0 0 0"/>
      <geometry>
        <mesh filename="package://victor_description/meshes/robotiq_3finger/palm_visual.stl"/>
      </geometry>
      <material name="DarkGray"/>
    </visual>
    <collision>
      <origin rpy="0 0 0" xyz="0 0 0"/>
      <geometry>
        <mesh filename="package://victor_description/meshes/robotiq_3finger/palm_collision.stl"/>
      </geometry>
      <material name="DarkGray"/>
    </collision>
  </link>
  <!-- Palm surface aligned with the gripper axis -->
  <joint name="victor_right_gripper_palm_surface_joint" type="fixed">
    <parent link="victor_right_gripper_palm"/>
    <child link="victor_right_gripper_palm_surface"/>
    <origin rpy="0 0 0" xyz="0 0 0.092075"/>
  </joint>
  <link name="victor_right_gripper_palm_surface">
        </link>
  <!-- Kuka internal frame has been changed to match our external usage, so identity transform -->
  <joint name="victor_right_gripper_palm_surface_kuka_joint" type="fixed">
    <parent link="victor_right_gripper_palm_surface"/>
    <child link="victor_right_gripper_palm_surface_kuka"/>
    <origin rpy="0 0 0" xyz="0 0 0"/>
  </joint>
  <link name="victor_right_gripper_palm_surface_kuka">
        </link>
  <!-- Finger A -->
  <joint name="victor_right_gripper_fingerA_knuckle" type="fixed">
    <origin rpy="0 0 0" xyz="0.02225040 0 0.06111875"/>
    <parent link="victor_right_gripper_palm"/>
    <child link="victor_right_gripper_fingerA_base"/>
  </joint>
  <link name="victor_right_gripper_fingerA_base">
    <inertial>
      <origin rpy="0 0 0" xyz="0 0 0"/>
      <mass value="1"/>
      <inertia ixx="0.01" ixy="0" ixz="0" iyy="0.01" iyz="0" izz="0.01"/>
    </inertial>
    <visual>
      <origin rpy="0 0 0" xyz="0 0 0"/>
      <geometry>
        <mesh filename="package://victor_description/meshes/robotiq_3finger/finger_link1_base_visual.stl"/>
      </geometry>
      <material name="DarkGray"/>
    </visual>
    <collision>
      <origin rpy="0 0 0" xyz="0 0 0"/>
      <geometry>
        <mesh filename="package://victor_description/meshes/robotiq_3finger/finger_link1_base_visual.stl"/>
      </geometry>
      <material name="DarkGray"/>
    </collision>
  </link>
  <!-- Joint 2 (base-prox) -->
  <joint name="victor_right_gripper_fingerA_joint_2" type="revolute">
    <parent link="victor_right_gripper_fingerA_base"/>
    <child link="victor_right_gripper_fingerA_prox"/>
    <origin rpy="0 0.610865238198 0" xyz="0.02225000 0 0.02151380"/>
    <axis xyz="0 -1 0"/>
    <limit effort="300" lower="0" upper="1.2217304763960307" velocity="10"/>
    <safety_controller k_position="100" k_velocity="2" soft_lower_limit="-0.610865238198" soft_upper_limit="0.610865238198"/>
    <dynamics damping="0.5"/>
  </joint>
  <link name="victor_right_gripper_fingerA_prox">
    <inertial>
      <origin rpy="0 0 0" xyz="0 0 0"/>
      <mass value="1"/>
      <inertia ixx="0.01" ixy="0" ixz="0" iyy="0.01" iyz="0" izz="0.01"/>
    </inertial>
    <visual>
      <origin rpy="0 0 0" xyz="0 0 0"/>
      <geometry>
        <mesh filename="package://victor_description/meshes/robotiq_3finger/finger_link2_prox_visual.stl"/>
      </geometry>
      <material name="DarkGray"/>
    </visual>
    <collision>
      <origin rpy="0 0 0" xyz="0 0 0"/>
      <geometry>
        <mesh filename="package://victor_description/meshes/robotiq_3finger/finger_link2_prox_collision.stl"/>
      </geometry>
      <material name="DarkGray"/>
    </collision>
  </link>
  <!-- Joint 3 (prox-med) -->
  <joint name="victor_right_gripper_fingerA_joint_3" type="revolute">
    <parent link="victor_right_gripper_fingerA_prox"/>
    <child link="victor_right_gripper_fingerA_med"/>
    <origin rpy="0 0 0" xyz="0 0 0.05715000"/>
    <axis xyz="0 -1 0"/>
    <limit effort="300" lower="-1" upper="1" velocity="10"/>
    <safety_controller k_position="100" k_velocity="2" soft_lower_limit="0.0" soft_upper_limit="1.57079632679"/>
    <dynamics damping="0.5"/>
  </joint>
  <link name="victor_right_gripper_fingerA_med">
    <inertial>
      <origin rpy="0 0 0" xyz="0 0 0"/>
      <mass value="1"/>
      <inertia ixx="0.01" ixy="0" ixz="0" iyy="0.01" iyz="0" izz="0.01"/>
    </inertial>
    <visual>
      <origin rpy="0 0 0" xyz="0 0 0"/>
      <geometry>
        <mesh filename="package://victor_description/meshes/robotiq_3finger/finger_link3_med_visual.stl"/>
      </geometry>
      <material name="DarkGray"/>
    </visual>
    <collision>
      <origin rpy="0 0 0" xyz="0 0 0"/>
      <geometry>
        <mesh filename="package://victor_description/meshes/robotiq_3finger/finger_link3_med_collision.stl"/>
      </geometry>
      <material name="DarkGray"/>
    </collision>
  </link>
  <!-- Joint 4 (med-dist) -->
  <joint name="victor_right_gripper_fingerA_joint_4" type="revolute">
    <parent link="victor_right_gripper_fingerA_med"/>
    <child link="victor_right_gripper_fingerA_dist"/>
    <origin rpy="0 -0.436332312999 0" xyz="0 0 0.03810000"/>
    <axis xyz="0 -1 0"/>
    <limit effort="300" lower="-1" upper="1" velocity="10"/>
    <safety_controller k_position="100" k_velocity="2" soft_lower_limit="-0.436332312999" soft_upper_limit="1.27409035396"/>
    <dynamics damping="0.5"/>
  </joint>
  <link name="victor_right_gripper_fingerA_dist">
    <inertial>
      <origin rpy="0 0 0" xyz="0 0 0"/>
      <mass value="1"/>
      <inertia ixx="0.01" ixy="0" ixz="0" iyy="0.01" iyz="0" izz="0.01"/>
    </inertial>
    <visual>
      <origin rpy="0 0 0" xyz="0 0 0"/>
      <geometry>
        <mesh filename="package://victor_description/meshes/robotiq_3finger/finger_link4_dist_visual.stl"/>
      </geometry>
      <material name="DarkGray"/>
    </visual>
    <collision>
      <origin rpy="0 0 0" xyz="0 0 0"/>
      <geometry>
        <mesh filename="package://victor_description/meshes/robotiq_3finger/finger_link4_dist_collision.stl"/>
      </geometry>
      <material name="DarkGray"/>
    </collision>
  </link>
  <!-- Finger B -->
  <joint name="victor_right_gripper_fingerB_knuckle" type="revolute">
    <origin rpy="0 0 3.14159265359" xyz="-0.02230120 0.03651250 0.06111875"/>
    <parent link="victor_right_gripper_palm"/>
    <child link="victor_right_gripper_fingerB_base"/>
    <axis xyz="-1 0 0"/>
    <limit effort="300" lower="-0.279252680319" upper="0.174532925199" velocity="10"/>
    <safety_controller k_position="100" k_velocity="2" soft_lower_limit="-0.244346095279" soft_upper_limit="0.13962634016"/>
    <dynamics damping="0.5"/>
  </joint>
  <link name="victor_right_gripper_fingerB_base">
    <inertial>
      <origin rpy="0 0 0" xyz="0 0 0"/>
      <mass value="1"/>
      <inertia ixx="0.01" ixy="0" ixz="0" iyy="0.01" iyz="0" izz="0.01"/>
    </inertial>
    <visual>
      <origin rpy="0 0 0" xyz="0 0 0"/>
      <geometry>
        <mesh filename="package://victor_description/meshes/robotiq_3finger/finger_link1_base_visual.stl"/>
      </geometry>
      <material name="DarkGray"/>
    </visual>
    <collision>
      <origin rpy="0 0 0" xyz="0 0 0"/>
      <geometry>
        <mesh filename="package://victor_description/meshes/robotiq_3finger/finger_link1_base_visual.stl"/>
      </geometry>
      <material name="DarkGray"/>
    </collision>
  </link>
  <!-- Joint 2 (base-prox) -->
  <joint name="victor_right_gripper_fingerB_joint_2" type="revolute">
    <parent link="victor_right_gripper_fingerB_base"/>
    <child link="victor_right_gripper_fingerB_prox"/>
    <origin rpy="0 0.610865238198 0" xyz="0.02225000 0 0.02151380"/>
    <axis xyz="0 -1 0"/>
    <limit effort="300" lower="0" upper="1.2217304763960307" velocity="10"/>
    <safety_controller k_position="100" k_velocity="2" soft_lower_limit="-0.610865238198" soft_upper_limit="0.610865238198"/>
    <dynamics damping="0.5"/>
  </joint>
  <link name="victor_right_gripper_fingerB_prox">
    <inertial>
      <origin rpy="0 0 0" xyz="0 0 0"/>
      <mass value="1"/>
      <inertia ixx="0.01" ixy="0" ixz="0" iyy="0.01" iyz="0" izz="0.01"/>
    </inertial>
    <visual>
      <origin rpy="0 0 0" xyz="0 0 0"/>
      <geometry>
        <mesh filename="package://victor_description/meshes/robotiq_3finger/finger_link2_prox_visual.stl"/>
      </geometry>
      <material name="DarkGray"/>
    </visual>
    <collision>
      <origin rpy="0 0 0" xyz="0 0 0"/>
      <geometry>
        <mesh filename="package://victor_description/meshes/robotiq_3finger/finger_link2_prox_collision.stl"/>
      </geometry>
      <material name="DarkGray"/>
    </collision>
  </link>
  <!-- Joint 3 (prox-med) -->
  <joint name="victor_right_gripper_fingerB_joint_3" type="revolute">
    <parent link="victor_right_gripper_fingerB_prox"/>
    <child link="victor_right_gripper_fingerB_med"/>
    <origin rpy="0 0 0" xyz="0 0 0.05715000"/>
    <axis xyz="0 -1 0"/>
    <limit effort="300" lower="-1" upper="1" velocity="10"/>
    <safety_controller k_position="100" k_velocity="2" soft_lower_limit="0.0" soft_upper_limit="1.57079632679"/>
    <dynamics damping="0.5"/>
  </joint>
  <link name="victor_right_gripper_fingerB_med">
    <inertial>
      <origin rpy="0 0 0" xyz="0 0 0"/>
      <mass value="1"/>
      <inertia ixx="0.01" ixy="0" ixz="0" iyy="0.01" iyz="0" izz="0.01"/>
    </inertial>
    <visual>
      <origin rpy="0 0 0" xyz="0 0 0"/>
      <geometry>
        <mesh filename="package://victor_description/meshes/robotiq_3finger/finger_link3_med_visual.stl"/>
      </geometry>
      <material name="DarkGray"/>
    </visual>
    <collision>
      <origin rpy="0 0 0" xyz="0 0 0"/>
      <geometry>
        <mesh filename="package://victor_description/meshes/robotiq_3finger/finger_link3_med_collision.stl"/>
      </geometry>
      <material name="DarkGray"/>
    </collision>
  </link>
  <!-- Joint 4 (med-dist) -->
  <joint name="victor_right_gripper_fingerB_joint_4" type="revolute">
    <parent link="victor_right_gripper_fingerB_med"/>
    <child link="victor_right_gripper_fingerB_dist"/>
    <origin rpy="0 -0.436332312999 0" xyz="0 0 0.03810000"/>
    <axis xyz="0 -1 0"/>
    <limit effort="300" lower="-1" upper="1" velocity="10"/>
    <safety_controller k_position="100" k_velocity="2" soft_lower_limit="-0.436332312999" soft_upper_limit="1.27409035396"/>
    <dynamics damping="0.5"/>
  </joint>
  <link name="victor_right_gripper_fingerB_dist">
    <inertial>
      <origin rpy="0 0 0" xyz="0 0 0"/>
      <mass value="1"/>
      <inertia ixx="0.01" ixy="0" ixz="0" iyy="0.01" iyz="0" izz="0.01"/>
    </inertial>
    <visual>
      <origin rpy="0 0 0" xyz="0 0 0"/>
      <geometry>
        <mesh filename="package://victor_description/meshes/robotiq_3finger/finger_link4_dist_visual.stl"/>
      </geometry>
      <material name="DarkGray"/>
    </visual>
    <collision>
      <origin rpy="0 0 0" xyz="0 0 0"/>
      <geometry>
        <mesh filename="package://victor_description/meshes/robotiq_3finger/finger_link4_dist_collision.stl"/>
      </geometry>
      <material name="DarkGray"/>
    </collision>
  </link>
  <!-- Finger C -->
  <joint name="victor_right_gripper_fingerC_knuckle" type="revolute">
    <origin rpy="0 0 3.14159265359" xyz="-0.02230120 -0.03651250 0.06111875"/>
    <parent link="victor_right_gripper_palm"/>
    <child link="victor_right_gripper_fingerC_base"/>
    <axis xyz="1 0 0"/>
    <limit effort="300" lower="-0.279252680319" upper="0.174532925199" velocity="10"/>
    <safety_controller k_position="100" k_velocity="2" soft_lower_limit="-0.244346095279" soft_upper_limit="0.13962634016"/>
    <dynamics damping="0.5"/>
  </joint>
  <link name="victor_right_gripper_fingerC_base">
    <inertial>
      <origin rpy="0 0 0" xyz="0 0 0"/>
      <mass value="1"/>
      <inertia ixx="0.01" ixy="0" ixz="0" iyy="0.01" iyz="0" izz="0.01"/>
    </inertial>
    <visual>
      <origin rpy="0 0 0" xyz="0 0 0"/>
      <geometry>
        <mesh filename="package://victor_description/meshes/robotiq_3finger/finger_link1_base_visual.stl"/>
      </geometry>
      <material name="DarkGray"/>
    </visual>
    <collision>
      <origin rpy="0 0 0" xyz="0 0 0"/>
      <geometry>
        <mesh filename="package://victor_description/meshes/robotiq_3finger/finger_link1_base_visual.stl"/>
      </geometry>
      <material name="DarkGray"/>
    </collision>
  </link>
  <!-- Joint 2 (base-prox) -->
  <joint name="victor_right_gripper_fingerC_joint_2" type="revolute">
    <parent link="victor_right_gripper_fingerC_base"/>
    <child link="victor_right_gripper_fingerC_prox"/>
    <origin rpy="0 0.610865238198 0" xyz="0.02225000 0 0.02151380"/>
    <axis xyz="0 -1 0"/>
    <limit effort="300" lower="0" upper="1.2217304763960307" velocity="10"/>
    <safety_controller k_position="100" k_velocity="2" soft_lower_limit="-0.610865238198" soft_upper_limit="0.610865238198"/>
    <dynamics damping="0.5"/>
  </joint>
  <link name="victor_right_gripper_fingerC_prox">
    <inertial>
      <origin rpy="0 0 0" xyz="0 0 0"/>
      <mass value="1"/>
      <inertia ixx="0.01" ixy="0" ixz="0" iyy="0.01" iyz="0" izz="0.01"/>
    </inertial>
    <visual>
      <origin rpy="0 0 0" xyz="0 0 0"/>
      <geometry>
        <mesh filename="package://victor_description/meshes/robotiq_3finger/finger_link2_prox_visual.stl"/>
      </geometry>
      <material name="DarkGray"/>
    </visual>
    <collision>
      <origin rpy="0 0 0" xyz="0 0 0"/>
      <geometry>
        <mesh filename="package://victor_description/meshes/robotiq_3finger/finger_link2_prox_collision.stl"/>
      </geometry>
      <material name="DarkGray"/>
    </collision>
  </link>
  <!-- Joint 3 (prox-med) -->
  <joint name="victor_right_gripper_fingerC_joint_3" type="revolute">
    <parent link="victor_right_gripper_fingerC_prox"/>
    <child link="victor_right_gripper_fingerC_med"/>
    <origin rpy="0 0 0" xyz="0 0 0.05715000"/>
    <axis xyz="0 -1 0"/>
    <limit effort="300" lower="-1" upper="1" velocity="10"/>
    <safety_controller k_position="100" k_velocity="2" soft_lower_limit="0.0" soft_upper_limit="1.57079632679"/>
    <dynamics damping="0.5"/>
  </joint>
  <link name="victor_right_gripper_fingerC_med">
    <inertial>
      <origin rpy="0 0 0" xyz="0 0 0"/>
      <mass value="1"/>
      <inertia ixx="0.01" ixy="0" ixz="0" iyy="0.01" iyz="0" izz="0.01"/>
    </inertial>
    <visual>
      <origin rpy="0 0 0" xyz="0 0 0"/>
      <geometry>
        <mesh filename="package://victor_description/meshes/robotiq_3finger/finger_link3_med_visual.stl"/>
      </geometry>
      <material name="DarkGray"/>
    </visual>
    <collision>
      <origin rpy="0 0 0" xyz="0 0 0"/>
      <geometry>
        <mesh filename="package://victor_description/meshes/robotiq_3finger/finger_link3_med_collision.stl"/>
      </geometry>
      <material name="DarkGray"/>
    </collision>
  </link>
  <!-- Joint 4 (med-dist) -->
  <joint name="victor_right_gripper_fingerC_joint_4" type="revolute">
    <parent link="victor_right_gripper_fingerC_med"/>
    <child link="victor_right_gripper_fingerC_dist"/>
    <origin rpy="0 -0.436332312999 0" xyz="0 0 0.03810000"/>
    <axis xyz="0 -1 0"/>
    <limit effort="300" lower="-1" upper="1" velocity="10"/>
    <safety_controller k_position="100" k_velocity="2" soft_lower_limit="-0.436332312999" soft_upper_limit="1.27409035396"/>
    <dynamics damping="0.5"/>
  </joint>
  <link name="victor_right_gripper_fingerC_dist">
    <inertial>
      <origin rpy="0 0 0" xyz="0 0 0"/>
      <mass value="1"/>
      <inertia ixx="0.01" ixy="0" ixz="0" iyy="0.01" iyz="0" izz="0.01"/>
    </inertial>
    <visual>
      <origin rpy="0 0 0" xyz="0 0 0"/>
      <geometry>
        <mesh filename="package://victor_description/meshes/robotiq_3finger/finger_link4_dist_visual.stl"/>
      </geometry>
      <material name="DarkGray"/>
    </visual>
    <collision>
      <origin rpy="0 0 0" xyz="0 0 0"/>
      <geometry>
        <mesh filename="package://victor_description/meshes/robotiq_3finger/finger_link4_dist_collision.stl"/>
      </geometry>
      <material name="DarkGray"/>
    </collision>
  </link>
</robot>

