<?xml version="1.0" ?>
<!-- =================================================================================== -->
<!-- |    This document was autogenerated by xacro from hdt_michigan.xacro             | -->
<!-- |    EDITING THIS FILE BY HAND IS NOT RECOMMENDED                                 | -->
<!-- =================================================================================== -->
<robot name="hdt_michigan">
  <!-- materials -->
  <material name="black">
    <color rgba="0.0 0.0 0.0 1.0"/>
  </material>
  <material name="grey">
    <color rgba="0.23529411764705882 0.23529411764705882 0.23529411764705882 1.0"/>
  </material>
  <material name="orange">
    <color rgba="1.0 0.5490196078431373 0.0 1.0"/>
  </material>
  <material name="maroon">
    <color rgba="0.5019607843137255 0.0 0.0 1.0"/>
  </material>
  <material name="white">
    <color rgba="1.0 1.0 1.0 1.0"/>
  </material>
  <material name="blue">
    <color rgba="0.01568627450980392 0.11764705882352941 0.25882352941176473 1.0"/>
  </material>
  <material name="maize">
    <color rgba="1.0 0.7803921568627451 0.17254901960784313 1.0"/>
  </material>
  <!-- mounting plate -->
  <gazebo reference="hdt_michigan_root">
    <selfCollide>true</selfCollide>
    <kinematic>1</kinematic>
  </gazebo>
  <gazebo reference="drive57">
    <material>Gazebo/FlatBlack</material>
    <selfCollide>true</selfCollide>
    <kinematic>1</kinematic>
  </gazebo>
  <gazebo reference="torso">
    <material>Gazebo/FlatBlack</material>
    <selfCollide>true</selfCollide>
    <kinematic>1</kinematic>
  </gazebo>
  <gazebo reference="drive42">
    <material>Gazebo/FlatBlack</material>
    <selfCollide>true</selfCollide>
    <kinematic>1</kinematic>
  </gazebo>
  <gazebo reference="leftshoulder">
    <material>Gazebo/FlatBlack</material>
    <selfCollide>true</selfCollide>
    <kinematic>1</kinematic>
  </gazebo>
  <gazebo reference="lefttube">
    <material>Gazebo/FlatBlack</material>
    <selfCollide>true</selfCollide>
    <kinematic>1</kinematic>
  </gazebo>
  <gazebo reference="leftforearm">
    <material>Gazebo/FlatBlack</material>
    <selfCollide>true</selfCollide>
    <kinematic>1</kinematic>
  </gazebo>
  <gazebo reference="drive46">
    <material>Gazebo/FlatBlack</material>
    <selfCollide>true</selfCollide>
    <kinematic>1</kinematic>
  </gazebo>
  <gazebo reference="leftwrist">
    <material>Gazebo/FlatBlack</material>
    <selfCollide>true</selfCollide>
    <kinematic>1</kinematic>
  </gazebo>
  <gazebo reference="drive50">
    <material>Gazebo/FlatBlack</material>
    <selfCollide>true</selfCollide>
    <kinematic>1</kinematic>
  </gazebo>
  <gazebo reference="leftgripper2_link">
    <material>Gazebo/FlatBlack</material>
    <selfCollide>true</selfCollide>
    <kinematic>1</kinematic>
    <maxContacts>1</maxContacts>
  </gazebo>
  <gazebo reference="leftgripper_link">
    <material>Gazebo/FlatBlack</material>
    <selfCollide>true</selfCollide>
    <kinematic>1</kinematic>
    <maxContacts>1</maxContacts>
  </gazebo>
  <gazebo reference="drive2">
    <material>Gazebo/Grey</material>
    <selfCollide>true</selfCollide>
    <kinematic>1</kinematic>
  </gazebo>
  <gazebo reference="rightshoulder">
    <material>Gazebo/FlatBlack</material>
    <selfCollide>true</selfCollide>
    <kinematic>1</kinematic>
  </gazebo>
  <gazebo reference="righttube">
    <material>Gazebo/Grey</material>
    <selfCollide>true</selfCollide>
    <kinematic>1</kinematic>
  </gazebo>
  <gazebo reference="rightforearm">
    <material>Gazebo/FlatBlack</material>
    <selfCollide>true</selfCollide>
    <kinematic>1</kinematic>
  </gazebo>
  <gazebo reference="drive6">
    <material>Gazebo/Grey</material>
    <selfCollide>true</selfCollide>
    <kinematic>1</kinematic>
  </gazebo>
  <gazebo reference="rightwrist">
    <material>Gazebo/FlatBlack</material>
    <selfCollide>true</selfCollide>
    <kinematic>1</kinematic>
  </gazebo>
  <gazebo reference="drive10">
    <material>Gazebo/Grey</material>
    <selfCollide>true</selfCollide>
    <kinematic>1</kinematic>
  </gazebo>
  <gazebo reference="rightgripper2_link">
    <material>Gazebo/Grey</material>
    <selfCollide>true</selfCollide>
    <kinematic>1</kinematic>
    <maxContacts>1</maxContacts>
  </gazebo>
  <gazebo reference="rightgripper_link">
    <material>Gazebo/Grey</material>
    <selfCollide>true</selfCollide>
    <kinematic>1</kinematic>
    <maxContacts>1</maxContacts>
  </gazebo>
  <gazebo reference="right_tool_joint">
    <preserveFixedJoint>true</preserveFixedJoint>
  </gazebo>
  <gazebo reference="left_tool_joint">
    <preserveFixedJoint>true</preserveFixedJoint>
  </gazebo>
  <!-- segment 0 -->
  <link name="root"/>
  <joint name="eef_left" type="fixed">
    <origin rpy="0 0 0" xyz="0 0 0"/>
    <parent link="root"/>
    <child link="end_effector_left"/>
  </joint>
  <link name="end_effector_left">
  </link>
  <!-- Left Pincers -->
  <joint name="leftgripper" type="revolute">
    <hdt id="50a" inertia="0.075" kmax="150" kmin="75"/>
    <axis xyz="0 0 1"/>
    <limit effort="35.0" lower="-0.1166" upper="1" velocity="0.5"/>
    <origin rpy="1.5707963267948966 -0.42 -1.5707963267948966" xyz="0 0.0135 0.068553"/>
    <parent link="end_effector_left"/>
    <child link="leftgripper_link"/>
    <dynamics damping="0.01" friction="0"/>
  </joint>
  <transmission name="leftgripper_transmissions">
    <type>transmission_interface/SimpleTransmission</type>
    <joint name="leftgripper">
      <hardwareInterface>hardware_interface/PositionJointInterface</hardwareInterface>
    </joint>
    <actuator name="leftgripper_motor">
      <mechanicalReduction>1</mechanicalReduction>
    </actuator>
  </transmission>
  <link name="leftgripper_link">
    <visual>
      <origin rpy="0 0 0" xyz="0 0 0"/>
      <geometry>
        <mesh filename="package://hdt_michigan_description/meshes/PINCER_FINGER.STL"/>
      </geometry>
      <material name="blue"/>
    </visual>
    <inertial>
      <origin rpy="0 0 0" xyz="0.034 0.055 0.007"/>
      <mass value="0.06821764"/>
      <inertia ixx="0.00007499" ixy="0" ixz="0" iyy="0.00002842" iyz="0" izz="0.00010118"/>
    </inertial>
  </link>
  <!-- Left EE 2 -->
  <!-- THIS IS THE SECOND PINCER, NEEDS TO MOVE EQUAL BUT OPPOSITE AS PINCER 1 -->
  <joint name="leftgripper2" type="revolute">
    <hdt id="50b" inertia="0.075" kmax="150" kmin="75"/>
    <axis xyz="0 0 1"/>
    <origin rpy="1.5707963267948966 -0.42 1.5707963267948966" xyz="0 -0.0135 0.068553"/>
    <parent link="end_effector_left"/>
    <child link="leftgripper2_link"/>
    <calibration rising="0.0"/>
    <dynamics damping="0.01" friction="0.01"/>
    <limit effort="35.0" lower="-0.1166" upper="1" velocity="0.5"/>
  </joint>
  <transmission name="leftgripper2_transmissions">
    <type>transmission_interface/SimpleTransmission</type>
    <joint name="leftgripper2">
      <hardwareInterface>hardware_interface/PositionJointInterface</hardwareInterface>
    </joint>
    <actuator name="leftgripper2_motor">
      <mechanicalReduction>1</mechanicalReduction>
    </actuator>
  </transmission>
  <link name="leftgripper2_link">
    <visual>
      <origin rpy="0 0 0" xyz="0 0 0"/>
      <geometry>
        <mesh filename="package://hdt_michigan_description/meshes/PINCER_FINGER.STL"/>
      </geometry>
      <material name="blue"/>
    </visual>
    <inertial>
      <origin rpy="0 0 0" xyz="0.034 0.055 0.007"/>
      <mass value="0.06821764"/>
      <inertia ixx="0.00007499" ixy="0" ixz="0" iyy="0.00002842" iyz="0" izz="0.00010118"/>
    </inertial>
  </link>
  
  <link name="left_tool">
    <inertial>
      <origin rpy="0 0 0" xyz="0 0 0"/>
      <mass value="0.001"/>
      <inertia ixx="0" ixy="0" ixz="0" iyy="0" iyz="0" izz="0"/>
    </inertial>
  </link>
  <joint name="left_tool_joint" type="fixed">
    <parent link="end_effector_left"/>
    <child link="left_tool"/>
    <origin rpy="0 0 0" xyz="0.0 0.0 0.181"/>
  </joint>
  

  <gazebo>
    <plugin filename="libgazebo_ros_control.so" name="gazebo_ros_control">
      <robotNamespace>hdt_michigan</robotNamespace>
      <legacyModeNS>false</legacyModeNS>
    </plugin>
  </gazebo>
  <gazebo>
    <plugin filename="libgazebo_ros_moveit_planning_scene.so" name="gazebo_ros_moveit_planning_scene">
      <robotName>hdt_michigan</robotName>
      <robotNamespace>hdt_michigan</robotNamespace>
      <!--  This must be the same as the root frame of the robot you're using -->
      <frameId>hdt_michigan_root</frameId>
      <excludedModels>collision_sphere</excludedModels>
      <scalePrimitivesFactor>1.1</scalePrimitivesFactor>
    </plugin>
  </gazebo>
  <link name="world"/>
  <joint name="world_joint" type="fixed">
    <parent link="world"/>
    <child link="root"/>
    <origin rpy="0.0 0.0 0.0" xyz="0.0 0.0 0.0"/>
  </joint>
</robot>

