<?xml version="1.0" ?>
<!-- =================================================================================== -->
<!-- |    This document was autogenerated by xacro from hdt_michigan_no_husky.xacro    | -->
<!-- |    EDITING THIS FILE BY HAND IS NOT RECOMMENDED                                 | -->
<!-- =================================================================================== -->
<robot>
  <material name="grey">
    <color rgba="0.23529411764705882 0.23529411764705882 0.23529411764705882 1.0"/>
  </material>
  <material name="orange">
    <color rgba="1.0 0.5490196078431373 0.0 1.0"/>
  </material>
  <material name="maroon">
    <color rgba="0.5019607843137255 0.0 0.0 1.0"/>
  </material>
  <material name="blue">
    <color rgba="0.01568627450980392 0.11764705882352941 0.25882352941176473 1.0"/>
  </material>
  <material name="maize">
    <color rgba="1.0 0.7803921568627451 0.17254901960784313 1.0"/>
  </material>
  <!-- mounting plate -->
  <gazebo reference="hdt_michigan_root">
    <selfCollide>true</selfCollide>
    <kinematic>1</kinematic>
  </gazebo>
  <gazebo reference="drive57">
    <material>Gazebo/FlatBlack</material>
    <selfCollide>true</selfCollide>
    <kinematic>1</kinematic>
  </gazebo>
  <gazebo reference="torso">
    <material>Gazebo/FlatBlack</material>
    <selfCollide>true</selfCollide>
    <kinematic>1</kinematic>
  </gazebo>
  <gazebo reference="drive42">
    <material>Gazebo/FlatBlack</material>
    <selfCollide>true</selfCollide>
    <kinematic>1</kinematic>
  </gazebo>
  <gazebo reference="leftshoulder">
    <material>Gazebo/FlatBlack</material>
    <selfCollide>true</selfCollide>
    <kinematic>1</kinematic>
  </gazebo>
  <gazebo reference="lefttube">
    <material>Gazebo/FlatBlack</material>
    <selfCollide>true</selfCollide>
    <kinematic>1</kinematic>
  </gazebo>
  <gazebo reference="leftforearm">
    <material>Gazebo/FlatBlack</material>
    <selfCollide>true</selfCollide>
    <kinematic>1</kinematic>
  </gazebo>
  <gazebo reference="drive46">
    <material>Gazebo/FlatBlack</material>
    <selfCollide>true</selfCollide>
    <kinematic>1</kinematic>
  </gazebo>
  <gazebo reference="leftwrist">
    <material>Gazebo/FlatBlack</material>
    <selfCollide>true</selfCollide>
    <kinematic>1</kinematic>
  </gazebo>
  <gazebo reference="drive50">
    <material>Gazebo/FlatBlack</material>
    <selfCollide>true</selfCollide>
    <kinematic>1</kinematic>
  </gazebo>
  <gazebo reference="leftgripper2_link">
    <material>Gazebo/FlatBlack</material>
    <selfCollide>true</selfCollide>
    <kinematic>1</kinematic>
    <maxContacts>1</maxContacts>
  </gazebo>
  <gazebo reference="leftgripper_link">
    <material>Gazebo/FlatBlack</material>
    <selfCollide>true</selfCollide>
    <kinematic>1</kinematic>
    <maxContacts>1</maxContacts>
  </gazebo>
  <gazebo reference="drive2">
    <material>Gazebo/Grey</material>
    <selfCollide>true</selfCollide>
    <kinematic>1</kinematic>
  </gazebo>
  <gazebo reference="rightshoulder">
    <material>Gazebo/FlatBlack</material>
    <selfCollide>true</selfCollide>
    <kinematic>1</kinematic>
  </gazebo>
  <gazebo reference="righttube">
    <material>Gazebo/Grey</material>
    <selfCollide>true</selfCollide>
    <kinematic>1</kinematic>
  </gazebo>
  <gazebo reference="rightforearm">
    <material>Gazebo/FlatBlack</material>
    <selfCollide>true</selfCollide>
    <kinematic>1</kinematic>
  </gazebo>
  <gazebo reference="drive6">
    <material>Gazebo/Grey</material>
    <selfCollide>true</selfCollide>
    <kinematic>1</kinematic>
  </gazebo>
  <gazebo reference="rightwrist">
    <material>Gazebo/FlatBlack</material>
    <selfCollide>true</selfCollide>
    <kinematic>1</kinematic>
  </gazebo>
  <gazebo reference="drive10">
    <material>Gazebo/Grey</material>
    <selfCollide>true</selfCollide>
    <kinematic>1</kinematic>
  </gazebo>
  <gazebo reference="rightgripper2_link">
    <material>Gazebo/Grey</material>
    <selfCollide>true</selfCollide>
    <kinematic>1</kinematic>
    <maxContacts>1</maxContacts>
  </gazebo>
  <gazebo reference="rightgripper_link">
    <material>Gazebo/Grey</material>
    <selfCollide>true</selfCollide>
    <kinematic>1</kinematic>
    <maxContacts>1</maxContacts>
  </gazebo>
  <gazebo reference="right_tool_joint">
    <preserveFixedJoint>true</preserveFixedJoint>
  </gazebo>
  <gazebo reference="left_tool_joint">
    <preserveFixedJoint>true</preserveFixedJoint>
  </gazebo>
  <link name="hdt_michigan_root"/>
  <link name="base"/>
  <joint name="base" type="fixed">
    <origin rpy="0 0 0" xyz="0 0 0"/>
    <parent link="hdt_michigan_root"/>
    <child link="base"/>
  </joint>
  <link name="realsense">
    <collision name="realsense_collision">
      <origin rpy="0 0 0" xyz="0.038 0 0.48"/>
      <geometry>
        <box size="0.26 0.15 0.2"/>
      </geometry>
    </collision>
    <visual name="realsense_visual">
      <origin rpy="1.5707 0 3.14159" xyz="0.035 0.032 0.521"/>
      <geometry>
        <mesh filename="package://hdt_michigan_description/meshes/VAL_REALSENSE_MOUNT.STL" scale="1.0 1.0 1.0"/>
      </geometry>
      <material name="grey"/>
    </visual>
  </link>
  <joint name="realsense_joint" type="fixed">
    <origin rpy="0 0 0" xyz="0 0 0"/>
    <parent link="torso"/>
    <child link="realsense"/>
  </joint>
  <!-- mounting plate -->
  <joint name="pedestal_joint" type="fixed">
    <origin rpy="-1.5707963267948966 0 0" xyz="0 0 0"/>
    <parent link="base"/>
    <child link="pedestal_link"/>
  </joint>
  <link name="pedestal_link">
    <collision>
      <origin rpy="0 0 0" xyz="0 0 0"/>
      <geometry>
        <mesh filename="package://hdt_michigan_description/meshes/PEDESTAL_ASSEMBLY.STL" scale="1.0 1.0 1.0"/>
      </geometry>
    </collision>
    <visual>
      <origin rpy="0 0 0" xyz="0 0 0"/>
      <geometry>
        <mesh filename="package://hdt_michigan_description/meshes/PEDESTAL_ASSEMBLY.STL"/>
      </geometry>
      <material name="maize"/>
    </visual>
    <inertial>
      <origin rpy="0 0 0" xyz="0.00824926 0.00007832 0.02192315"/>
      <mass value="0.25375688"/>
      <inertia ixx="0.00014143" ixy="0.0" ixz="0.0" iyy="0.00016740" iyz="0.0" izz="0.00020523"/>
    </inertial>
  </link>
  <!-- Drive 56 -->
  <joint name="joint0" type="fixed">
    <origin rpy="-1.5707963267948966 0 0" xyz="0 0 .0891"/>
    <parent link="pedestal_link"/>
    <child link="drive56"/>
  </joint>
  <link name="drive56">
    <collision>
      <origin rpy="0 0 0" xyz="0 0 0"/>
      <geometry>
        <mesh filename="package://hdt_michigan_description/meshes/MK4_MT.STL" scale="1.0 1.0 1.0"/>
      </geometry>
    </collision>
    <visual>
      <origin rpy="0 0 0" xyz="0 0 0"/>
      <geometry>
        <mesh filename="package://hdt_michigan_description/meshes/MK4_MT.STL"/>
      </geometry>
      <material name="blue"/>
    </visual>
    <inertial>
      <origin rpy="0 0 0" xyz="-0.00004358 0.00244867 0.00739686"/>
      <mass value="1.73427319"/>
      <inertia ixx="0.00212963" ixy="-0.00000090" ixz="-0.00000052" iyy="0.00199851" iyz="-0.00004418" izz="0.00138126"/>
    </inertial>
  </link>
  <!-- Drive 57 -->
  <joint name="joint56" type="revolute">
    <hdt id="56" inertia="0.1" kmax="200" kmin="100"/>
    <axis xyz="0 -1 0"/>
    <limit effort="180.0" lower="-6.2" upper="6.2" velocity="0.45"/>
    <origin rpy="1.5707963267948966 0 1.5707963267948966" xyz="0 0 -.082642"/>
    <parent link="drive56"/>
    <child link="drive57"/>
    <dynamics damping="2.0" friction="0.01"/>
  </joint>
  <transmission name="joint56_transmissions">
    <type>transmission_interface/SimpleTransmission</type>
    <joint name="joint56">
      <hardwareInterface>hardware_interface/PositionJointInterface</hardwareInterface>
    </joint>
    <actuator name="joint56_motor">
      <mechanicalReduction>1</mechanicalReduction>
    </actuator>
  </transmission>
  <link name="drive57">
    <collision>
      <origin rpy="0 0 0" xyz="0 0 0"/>
      <geometry>
        <mesh filename="package://hdt_michigan_description/meshes/MK4_MT.STL" scale="1.0 1.0 1.0"/>
      </geometry>
    </collision>
    <visual>
      <origin rpy="0 0 0" xyz="0 0 0"/>
      <geometry>
        <mesh filename="package://hdt_michigan_description/meshes/MK4_MT.STL"/>
      </geometry>
      <material name="blue"/>
    </visual>
    <inertial>
      <origin rpy="0 0 0" xyz="-0.00003658 0.00177045 0.00631346"/>
      <mass value="1.39278013"/>
      <inertia ixx="0.00159582" ixy="-0.00000077" ixz="-0.00000081" iyy="0.00151230" iyz="-0.00002261" izz="0.00105406"/>
    </inertial>
  </link>
  <!-- torso bracket -->
  <joint name="joint57" type="revolute">
    <hdt id="57" inertia="0.1" kmax="200" kmin="100"/>
    <axis xyz="-1 0 0"/>
    <limit effort="360.0" lower="-1.5707963267948966" upper="1.5707963267948966" velocity="0.45"/>
    <origin rpy="1.5707963267948966 -1.5707963267948966 0" xyz="0 0 -.04085"/>
    <parent link="drive57"/>
    <child link="torso"/>
    <dynamics damping="1.0" friction="0.01"/>
  </joint>
  <transmission name="joint57_transmissions">
    <type>transmission_interface/SimpleTransmission</type>
    <joint name="joint57">
      <hardwareInterface>hardware_interface/PositionJointInterface</hardwareInterface>
    </joint>
    <actuator name="joint57_motor">
      <mechanicalReduction>1</mechanicalReduction>
    </actuator>
  </transmission>
  <link name="torso">
    <collision>
      <origin rpy="0 0 0" xyz="0 0 0"/>
      <geometry>
        <mesh filename="package://hdt_michigan_description/meshes/TORSO.STL" scale="1.0 1.0 1.0"/>
      </geometry>
    </collision>
    <visual>
      <origin rpy="0 0 0" xyz="0 0 0"/>
      <geometry>
        <mesh filename="package://hdt_michigan_description/meshes/TORSO.STL"/>
      </geometry>
      <material name="maize"/>
    </visual>
    <inertial>
      <origin rpy="0 0 0" xyz="0.00013570 -0.04958110 0.01659126"/>
      <mass value="0.48998269"/>
      <inertia ixx="0.00762375" ixy="0" ixz="0" iyy="0.01156795" iyz="0" izz="0.00440141"/>
    </inertial>
  </link>
  <!-- Drive 41 -->
  <joint name="left0" type="fixed">
    <origin rpy="-1.5707963267948966 0 -1.5707963267948966" xyz="-.092094 0 .44399"/>
    <parent link="torso"/>
    <child link="drive41"/>
  </joint>
  <link name="drive41">
    <collision>
      <origin rpy="0 0 0" xyz="0 0 0"/>
      <geometry>
        <mesh filename="package://hdt_michigan_description/meshes/MK4_MT.STL" scale="1.0 1.0 1.0"/>
      </geometry>
    </collision>
    <visual>
      <origin rpy="0 0 0" xyz="0 0 0"/>
      <geometry>
        <mesh filename="package://hdt_michigan_description/meshes/MK4_MT.STL"/>
      </geometry>
      <material name="blue"/>
    </visual>
    <inertial>
      <origin rpy="0 0 0" xyz="-0.00004358 0.00244867 0.00739686"/>
      <mass value="1.73427319"/>
      <inertia ixx="0.00212963" ixy="0.0" ixz="0.0" iyy="0.00199851" iyz="0.0" izz="0.00138126"/>
    </inertial>
  </link>
  <!-- Drive 42 -->
  <joint name="joint41" type="revolute">
    <hdt id="41" inertia="0.1" kmax="200" kmin="100"/>
    <axis xyz="0 1 0"/>
    <limit effort="180.0" lower="-6.2" upper="6.2" velocity="0.45"/>
    <origin rpy="1.5707963267948966 0 -1.5707963267948966" xyz="0 0 -.082642"/>
    <parent link="drive41"/>
    <child link="drive42"/>
    <dynamics damping="1.0" friction="0.01"/>
  </joint>
  <transmission name="joint41_transmissions">
    <type>transmission_interface/SimpleTransmission</type>
    <joint name="joint41">
      <hardwareInterface>hardware_interface/PositionJointInterface</hardwareInterface>
    </joint>
    <actuator name="joint41_motor">
      <mechanicalReduction>1</mechanicalReduction>
    </actuator>
  </transmission>
  <link name="drive42">
    <collision>
      <origin rpy="0 0 0" xyz="0 0 0"/>
      <geometry>
        <mesh filename="package://hdt_michigan_description/meshes/MK4_LT.STL" scale="1.0 1.0 1.0"/>
      </geometry>
    </collision>
    <visual>
      <origin rpy="0 0 0" xyz="0 0 0"/>
      <geometry>
        <mesh filename="package://hdt_michigan_description/meshes/MK4_LT.STL"/>
      </geometry>
      <material name="blue"/>
    </visual>
    <inertial>
      <origin rpy="0 0 0" xyz="-0.00003658 0.00177045 0.00631346"/>
      <mass value="1.39278013"/>
      <inertia ixx="0.00159582" ixy="-0.00000077" ixz="-0.00000081" iyy="0.00151230" iyz="-0.00002261" izz="0.00105406"/>
    </inertial>
  </link>
  <!-- Left Shoulder bracket -->
  <joint name="joint42" type="revolute">
    <hdt id="42" inertia="0.1" kmax="200" kmin="100"/>
    <axis xyz="0 0 1"/>
    <limit effort="90.0" lower="-.15" upper="3.141592653589793" velocity="0.45"/>
    <origin rpy="0 0 -1.5707963267948966" xyz="0 0 -.07526"/>
    <parent link="drive42"/>
    <child link="leftshoulder"/>
    <dynamics damping="1.0" friction="0.01"/>
  </joint>
  <transmission name="joint42_transmissions">
    <type>transmission_interface/SimpleTransmission</type>
    <joint name="joint42">
      <hardwareInterface>hardware_interface/PositionJointInterface</hardwareInterface>
    </joint>
    <actuator name="joint42_motor">
      <mechanicalReduction>1</mechanicalReduction>
    </actuator>
  </transmission>
  <link name="leftshoulder">
    <collision>
      <origin rpy="0 0 0" xyz="0 0 0"/>
      <geometry>
        <mesh filename="package://hdt_michigan_description/meshes/SHOULDER_BRACKET.STL" scale="1.0 1.0 1.0"/>
      </geometry>
    </collision>
    <visual>
      <origin rpy="0 0 0" xyz="0 0 0"/>
      <geometry>
        <mesh filename="package://hdt_michigan_description/meshes/SHOULDER_BRACKET.STL"/>
      </geometry>
      <material name="maize"/>
    </visual>
    <inertial>
      <origin rpy="0 0 0" xyz="0.00013570 -0.04958110 0.01659126"/>
      <mass value="0.48998269"/>
      <inertia ixx="0.00124111" ixy="-0.00000083" ixz="-0.00000019" iyy="0.00020695" iyz="0.00001359" izz="0.00132624"/>
    </inertial>
  </link>
  <!-- Drive 43 -->
  <joint name="leftshoulder" type="fixed">
    <origin rpy="-1.5707963267948966 0 0" xyz="0 -.1 .07526"/>
    <parent link="leftshoulder"/>
    <child link="drive43"/>
  </joint>
  <link name="drive43">
    <collision>
      <origin rpy="0 0 0" xyz="0 0 0"/>
      <geometry>
        <mesh filename="package://hdt_michigan_description/meshes/MK4_LT.STL" scale="1.0 1.0 1.0"/>
      </geometry>
    </collision>
    <visual>
      <origin rpy="0 0 0" xyz="0 0 0"/>
      <geometry>
        <mesh filename="package://hdt_michigan_description/meshes/MK4_LT.STL"/>
      </geometry>
      <material name="blue"/>
    </visual>
    <inertial>
      <origin rpy="0 0 0" xyz="-0.00003658 0.00177045 0.00631346"/>
      <mass value="1.39278013"/>
      <inertia ixx="0.00159582" ixy="-0.00000077" ixz="-0.00000081" iyy="0.00151230" iyz="-0.00002261" izz="0.00105406"/>
    </inertial>
  </link>
  <!-- Left Proximal tube -->
  <joint name="joint43" type="revolute">
    <hdt id="43" inertia="0.1" kmax="200" kmin="100"/>
    <axis xyz="0 0 -1"/>
    <limit effort="90.0" lower="-6.2" upper="6.2" velocity="0.45"/>
    <origin rpy="-3.141592653589793 0 0" xyz="0 0 -.115888"/>
    <parent link="drive43"/>
    <child link="lefttube"/>
    <dynamics damping="0.5" friction="0.01"/>
  </joint>
  <transmission name="joint43_transmissions">
    <type>transmission_interface/SimpleTransmission</type>
    <joint name="joint43">
      <hardwareInterface>hardware_interface/PositionJointInterface</hardwareInterface>
    </joint>
    <actuator name="joint43_motor">
      <mechanicalReduction>1</mechanicalReduction>
    </actuator>
  </transmission>
  <link name="lefttube">
    <collision>
      <origin rpy="0 1.5707963267948966 0" xyz="0 0 0"/>
      <geometry>
        <mesh filename="package://hdt_michigan_description/meshes/PROXIMAL_TUBE.STL" scale="1.0 1.0 1.0"/>
      </geometry>
    </collision>
    <visual>
      <origin rpy="0 1.5707963267948966 0" xyz="0 0 0"/>
      <geometry>
        <mesh filename="package://hdt_michigan_description/meshes/PROXIMAL_TUBE.STL"/>
      </geometry>
      <material name="maize"/>
    </visual>
    <inertial>
      <origin rpy="0 0 0" xyz="-0.00003112 0.00004034 -0.06064495"/>
      <mass value="0.30359918"/>
      <inertia ixx="0.00099336" ixy="0.00000000" ixz="-0.00000021" iyy="0.00099312" iyz="-0.00000024" izz="0.00020564"/>
    </inertial>
  </link>
  <!-- Drive 44 -->
  <joint name="lefttube" type="fixed">
    <origin rpy="-1.5707963267948966 0 1.5707963267948966" xyz="0 0 0.0486304"/>
    <parent link="lefttube"/>
    <child link="drive44"/>
  </joint>
  <link name="drive44">
    <collision>
      <origin rpy="0 0 0" xyz="0 0 0"/>
      <geometry>
        <mesh filename="package://hdt_michigan_description/meshes/MK4_LT.STL" scale="1.0 1.0 1.0"/>
      </geometry>
    </collision>
    <visual>
      <origin rpy="0 0 0" xyz="0 0 0"/>
      <geometry>
        <mesh filename="package://hdt_michigan_description/meshes/MK4_LT.STL"/>
      </geometry>
      <material name="blue"/>
    </visual>
    <inertial>
      <origin rpy="0 0 0" xyz="-0.00003658 0.00177045 0.00631346"/>
      <mass value="1.39278013"/>
      <inertia ixx="0.00159582" ixy="-0.00000077" ixz="-0.00000081" iyy="0.00151230" iyz="-0.00002261" izz="0.00105406"/>
    </inertial>
  </link>
  <!-- Left Forearm bracket -->
  <joint name="joint44" type="revolute">
    <hdt id="44" inertia="0.1" kmax="200" kmin="100"/>
    <axis xyz="0 0 1"/>
    <limit effort="90.0" lower="-3.141592653589793" upper="1.0" velocity="0.45"/>
    <origin rpy="0 0 1.5707963267948966" xyz="0 0 -.06758"/>
    <parent link="drive44"/>
    <child link="leftforearm"/>
    <dynamics damping="0.1" friction="0.01"/>
  </joint>
  <transmission name="joint44_transmissions">
    <type>transmission_interface/SimpleTransmission</type>
    <joint name="joint44">
      <hardwareInterface>hardware_interface/PositionJointInterface</hardwareInterface>
    </joint>
    <actuator name="joint44_motor">
      <mechanicalReduction>1</mechanicalReduction>
    </actuator>
  </transmission>
  <link name="leftforearm">
    <collision>
      <origin rpy="0 0 0" xyz="0 0 0"/>
      <geometry>
        <mesh filename="package://hdt_michigan_description/meshes/FOREARM_BRACKET.STL" scale="1.0 1.0 1.0"/>
      </geometry>
    </collision>
    <visual>
      <origin rpy="0 0 0" xyz="0 0 0"/>
      <geometry>
        <mesh filename="package://hdt_michigan_description/meshes/FOREARM_BRACKET.STL"/>
      </geometry>
      <material name="maize"/>
    </visual>
    <inertial>
      <origin rpy="0 0 0" xyz="-0.00009916 -0.03803734 0.01245969"/>
      <mass value="0.29009416"/>
      <inertia ixx="0.00060152" ixy="-0.00000038" ixz="0.00000003" iyy="0.00009927" iyz="-0.00000788" izz="0.00065009"/>
    </inertial>
  </link>
  <!-- Drive 45 -->
  <joint name="leftforearm" type="fixed">
    <origin rpy="-1.5707963267948966 0 0" xyz="0 -.17 0.05749"/>
    <parent link="leftforearm"/>
    <child link="drive45"/>
  </joint>
  <link name="drive45">
    <collision>
      <origin rpy="0 0 0" xyz="0 0 0"/>
      <geometry>
        <mesh filename="package://hdt_michigan_description/meshes/A35_DRIVE.STL" scale="1.0 1.0 1.0"/>
      </geometry>
    </collision>
    <visual>
      <origin rpy="0 0 0" xyz="0 0 0"/>
      <geometry>
        <mesh filename="package://hdt_michigan_description/meshes/A35_DRIVE.STL"/>
      </geometry>
      <material name="blue"/>
    </visual>
    <inertial>
      <origin rpy="0 0 0" xyz="0.00000913 0.00110529 -0.01094052"/>
      <mass value="0.30279069"/>
      <inertia ixx="0.00012394" ixy="-0.00000001" ixz="-0.00000007" iyy="0.00011824" iyz="0.00000325" izz="0.00008729"/>
    </inertial>
  </link>
  <!-- Drive 46 -->
  <joint name="joint45" type="revolute">
    <hdt id="45" inertia="0.1" kmax="200" kmin="100"/>
    <axis xyz="0 1 0"/>
    <limit effort="35.0" lower="-6.2" upper="6.2" velocity="2.0943951023931953"/>
    <origin rpy="1.5707963267948966 0 1.5707963267948966" xyz="0 0 -.067262"/>
    <parent link="drive45"/>
    <child link="drive46"/>
    <dynamics damping="0.01" friction="0.01"/>
  </joint>
  <transmission name="joint45_transmissions">
    <type>transmission_interface/SimpleTransmission</type>
    <joint name="joint45">
      <hardwareInterface>hardware_interface/PositionJointInterface</hardwareInterface>
    </joint>
    <actuator name="joint45_motor">
      <mechanicalReduction>1</mechanicalReduction>
    </actuator>
  </transmission>
  <link name="drive46">
    <collision>
      <origin rpy="0 0 0" xyz="0 0 0"/>
      <geometry>
        <mesh filename="package://hdt_michigan_description/meshes/A35_DRIVE.STL" scale="1.0 1.0 1.0"/>
      </geometry>
    </collision>
    <visual>
      <origin rpy="0 0 0" xyz="0 0 0"/>
      <geometry>
        <mesh filename="package://hdt_michigan_description/meshes/A35_DRIVE.STL"/>
      </geometry>
      <material name="blue"/>
    </visual>
    <inertial>
      <origin rpy="0 0 0" xyz="0.00000913 0.00110529 -0.01094052"/>
      <mass value="0.30279069"/>
      <inertia ixx="0.00012394" ixy="-0.00000001" ixz="-0.00000007" iyy="0.00011824" iyz="0.00000325" izz="0.00008729"/>
    </inertial>
  </link>
  <!-- Left wrist -->
  <joint name="joint46" type="revolute">
    <hdt id="46" inertia="0.1" kmax="200" kmin="100"/>
    <axis xyz="0 0 -1"/>
    <limit effort="35.0" lower="-1.5707963267948966" upper="1.5707963267948966" velocity="2.0943951023931953"/>
    <origin rpy="0 0 0" xyz="0 0 -.0566728"/>
    <parent link="drive46"/>
    <child link="leftwrist"/>
    <dynamics damping="0.01" friction="0.01"/>
  </joint>
  <transmission name="joint46_transmissions">
    <type>transmission_interface/SimpleTransmission</type>
    <joint name="joint46">
      <hardwareInterface>hardware_interface/PositionJointInterface</hardwareInterface>
    </joint>
    <actuator name="joint46_motor">
      <mechanicalReduction>1</mechanicalReduction>
    </actuator>
  </transmission>
  <link name="leftwrist">
    <collision>
      <origin rpy="0 0 0" xyz="0 0 0"/>
      <geometry>
        <mesh filename="package://hdt_michigan_description/meshes/A35_BRACKET.STL" scale="1.0 1.0 1.0"/>
      </geometry>
    </collision>
    <visual>
      <origin rpy="0 0 0" xyz="0 0 0"/>
      <geometry>
        <mesh filename="package://hdt_michigan_description/meshes/A35_BRACKET.STL"/>
      </geometry>
      <material name="maize"/>
    </visual>
    <inertial>
      <origin rpy="0 0 0" xyz="-0.00001212 -0.02930845 0.01300716"/>
      <mass value="0.14250708"/>
      <inertia ixx="0.00011554" ixy="0.00000005" ixz="-0.00000003" iyy="0.00003814" iyz="-0.00000988" izz="0.00012738"/>
    </inertial>
  </link>
  <!-- Drive 47 -->
  <joint name="leftwrist" type="fixed">
    <origin rpy="-1.5707963267948966 0 0" xyz="0 -.05 .0566728"/>
    <parent link="leftwrist"/>
    <child link="drive47"/>
  </joint>
  <link name="drive47">
    <collision>
      <origin rpy="0 0 0" xyz="0 0 0"/>
      <geometry>
        <mesh filename="package://hdt_michigan_description/meshes/A35_DRIVE.STL" scale="1.0 1.0 1.0"/>
      </geometry>
    </collision>
    <visual>
      <origin rpy="0 0 0" xyz="0 0 0"/>
      <geometry>
        <mesh filename="package://hdt_michigan_description/meshes/A35_DRIVE.STL"/>
      </geometry>
      <material name="blue"/>
    </visual>
    <inertial>
      <origin rpy="0 0 0" xyz="0.00000913 0.00110529 -0.01094052"/>
      <mass value="0.30279069"/>
      <inertia ixx="0.00012394" ixy="-0.00000001" ixz="-0.00000007" iyy="0.00011824" iyz="0.00000325" izz="0.00008729"/>
    </inertial>
  </link>
  <!-- Left Pincer Housing -->
  <joint name="joint47" type="revolute">
    <hdt id="47" inertia="0.1" kmax="200" kmin="100"/>
    <axis xyz="0 0 -1"/>
    <limit effort="35.0" lower="-6.2" upper="6.2" velocity="3.141592653589793"/>
    <origin rpy="3.141592653589793 0 3.141592653589793" xyz="0 0 -.036"/>
    <parent link="drive47"/>
    <child link="drive50"/>
    <dynamics damping="0.01" friction="0.01"/>
  </joint>
  <transmission name="joint47_transmissions">
    <type>transmission_interface/SimpleTransmission</type>
    <joint name="joint47">
      <hardwareInterface>hardware_interface/PositionJointInterface</hardwareInterface>
    </joint>
    <actuator name="joint47_motor">
      <mechanicalReduction>1</mechanicalReduction>
    </actuator>
  </transmission>
  <link name="drive50">
    </link>
  <joint name="housing_left" type="fixed">
    <origin rpy="0 0 0" xyz="0 0 0"/>
    <parent link="drive50"/>
    <child link="end_effector_left"/>
  </joint>
	  
  <link name="end_effector_left">
    <collision>
      <origin rpy="0 0 0" xyz="0 0 0"/>
      <geometry>
        <mesh filename="package://hdt_michigan_description/meshes/PINCER_HOUSING2.STL" scale="1.0 1.0 1.0"/>
      </geometry>
    </collision>
    <collision>
      <origin rpy="0 0 0" xyz="0.0625 0 0.045"/>
      <geometry>
        <box size="0.03 0.10 0.10"/>
      </geometry>
    </collision>
    <visual>
      <origin rpy="0 0 0" xyz="0 0 0"/>
      <geometry>
        <mesh filename="package://hdt_michigan_description/meshes/PINCER_HOUSING2.STL"/>
      </geometry>
      <material name="maize"/>
    </visual>
    <inertial>
      <origin rpy="-1.5707963267948966 0 0" xyz="-0.02828166 0.00000247 -0.01722827"/>
      <mass value="0.27265869"/>
      <inertia ixx="0.00009278" ixy="0.0" ixz="0.00000608" iyy="0.00010001" iyz="0.0" izz="0.00007523"/>
    </inertial>
  </link>

  <!-- Left Pincers -->
  <joint name="leftgripper" type="revolute">
    <hdt id="50a" inertia="0.075" kmax="150" kmin="75"/>
    <axis xyz="0 0 1"/>
    <limit effort="35.0" lower="-0.1166" upper="1" velocity="0.5"/>
    <origin rpy="1.5707963267948966 -0.42 -1.5707963267948966" xyz="0 0.0135 0.068553"/>
    <parent link="end_effector_left"/>
    <child link="leftgripper_link"/>
    <dynamics damping="0.01" friction="0"/>
  </joint>
  <transmission name="leftgripper_transmissions">
    <type>transmission_interface/SimpleTransmission</type>
    <joint name="leftgripper">
      <hardwareInterface>hardware_interface/PositionJointInterface</hardwareInterface>
    </joint>
    <actuator name="leftgripper_motor">
      <mechanicalReduction>1</mechanicalReduction>
    </actuator>
  </transmission>
  <link name="leftgripper_link">
    <collision>
      <origin rpy="0 0 0" xyz="0 0 0"/>
      <geometry>
        <mesh filename="package://hdt_michigan_description/meshes/PINCER_FINGER.STL" scale="1.0 1.0 1.0"/>
      </geometry>
    </collision>
    <visual>
      <origin rpy="0 0 0" xyz="0 0 0"/>
      <geometry>
        <mesh filename="package://hdt_michigan_description/meshes/PINCER_FINGER.STL"/>
      </geometry>
      <material name="blue"/>
    </visual>
    <inertial>
      <origin rpy="0 0 0" xyz="0.034 0.055 0.007"/>
      <mass value="0.06821764"/>
      <inertia ixx="0.00007499" ixy="0" ixz="0" iyy="0.00002842" iyz="0" izz="0.00010118"/>
    </inertial>
  </link>
  <!-- Left EE 2 -->
  <!-- THIS IS THE SECOND PINCER, NEEDS TO MOVE EQUAL BUT OPPOSITE AS PINCER 1 -->
  <joint name="leftgripper2" type="revolute">
    <hdt id="50b" inertia="0.075" kmax="150" kmin="75"/>
    <axis xyz="0 0 1"/>
    <origin rpy="1.5707963267948966 -0.42 1.5707963267948966" xyz="0 -0.0135 0.068553"/>
    <parent link="end_effector_left"/>
    <child link="leftgripper2_link"/>
    <calibration rising="0.0"/>
    <dynamics damping="0.01" friction="0.01"/>
    <limit effort="35.0" lower="-0.1166" upper="1" velocity="0.5"/>
  </joint>
  <transmission name="leftgripper2_transmissions">
    <type>transmission_interface/SimpleTransmission</type>
    <joint name="leftgripper2">
      <hardwareInterface>hardware_interface/PositionJointInterface</hardwareInterface>
    </joint>
    <actuator name="leftgripper2_motor">
      <mechanicalReduction>1</mechanicalReduction>
    </actuator>
  </transmission>
  <link name="leftgripper2_link">
    <collision>
      <origin rpy="0 0 0" xyz="0 0 0"/>
      <geometry>
        <mesh filename="package://hdt_michigan_description/meshes/PINCER_FINGER.STL" scale="1.0 1.0 1.0"/>
      </geometry>
    </collision>
    <visual>
      <origin rpy="0 0 0" xyz="0 0 0"/>
      <geometry>
        <mesh filename="package://hdt_michigan_description/meshes/PINCER_FINGER.STL"/>
      </geometry>
      <material name="blue"/>
    </visual>
    <inertial>
      <origin rpy="0 0 0" xyz="0.034 0.055 0.007"/>
      <mass value="0.06821764"/>
      <inertia ixx="0.00007499" ixy="0" ixz="0" iyy="0.00002842" iyz="0" izz="0.00010118"/>
    </inertial>
  </link>
  <!-- Drive 1 -->
  <joint name="right0" type="fixed">
    <origin rpy="-1.5707963267948966 0 1.5707963267948966" xyz=".167906 0 .44399"/>
    <parent link="torso"/>
    <child link="drive1"/>
  </joint>
  <link name="drive1">
    <collision>
      <origin rpy="0 0 0" xyz="0 0 0"/>
      <geometry>
        <mesh filename="package://hdt_michigan_description/meshes/MK4_MT.STL" scale="1.0 1.0 1.0"/>
      </geometry>
    </collision>
    <visual>
      <origin rpy="0 0 0" xyz="0 0 0"/>
      <geometry>
        <mesh filename="package://hdt_michigan_description/meshes/MK4_MT.STL"/>
      </geometry>
      <material name="blue"/>
    </visual>
    <inertial>
      <origin rpy="0 0 0" xyz="-0.00004358 0.00244867 0.00739686"/>
      <mass value="1.73427319"/>
      <inertia ixx="0.00212963" ixy="0.0" ixz="0.0" iyy="0.00199851" iyz="0.0" izz="0.00138126"/>
    </inertial>
  </link>
  <!-- Drive 2 -->
  <joint name="joint1" type="revolute">
    <hdt id="1" inertia="0.1" kmax="200" kmin="100"/>
    <axis xyz="0 -1 0"/>
    <limit effort="180.0" lower="-6.2" upper="6.2" velocity="0.45"/>
    <origin rpy="1.5707963267948966 0 1.5707963267948966" xyz="0 0 -.082642"/>
    <parent link="drive1"/>
    <child link="drive2"/>
    <dynamics damping="1.0" friction="0.01"/>
  </joint>
  <transmission name="joint1_transmissions">
    <type>transmission_interface/SimpleTransmission</type>
    <joint name="joint1">
      <hardwareInterface>hardware_interface/PositionJointInterface</hardwareInterface>
    </joint>
    <actuator name="joint1_motor">
      <mechanicalReduction>1</mechanicalReduction>
    </actuator>
  </transmission>
  <link name="drive2">
    <collision>
      <origin rpy="0 0 0" xyz="0 0 0"/>
      <geometry>
        <mesh filename="package://hdt_michigan_description/meshes/MK4_LT.STL" scale="1.0 1.0 1.0"/>
      </geometry>
    </collision>
    <visual>
      <origin rpy="0 0 0" xyz="0 0 0"/>
      <geometry>
        <mesh filename="package://hdt_michigan_description/meshes/MK4_LT.STL"/>
      </geometry>
      <material name="blue"/>
    </visual>
    <inertial>
      <origin rpy="0 0 0" xyz="-0.00003658 0.00177045 0.00631346"/>
      <mass value="1.39278013"/>
      <inertia ixx="0.00159582" ixy="-0.00000077" ixz="-0.00000081" iyy="0.00151230" iyz="-0.00002261" izz="0.00105406"/>
    </inertial>
  </link>
  <!-- Right Shoulder bracket -->
  <joint name="joint2" type="revolute">
    <hdt id="2" inertia="0.1" kmax="200" kmin="100"/>
    <axis xyz="0 0 1"/>
    <limit effort="90.0" lower="-3.141592653589793" upper=".15" velocity="0.45"/>
    <origin rpy="0 0 1.5707963267948966" xyz="0 0 -.07526"/>
    <parent link="drive2"/>
    <child link="rightshoulder"/>
    <dynamics damping="1.0" friction="0.01"/>
  </joint>
  <transmission name="joint2_transmissions">
    <type>transmission_interface/SimpleTransmission</type>
    <joint name="joint2">
      <hardwareInterface>hardware_interface/PositionJointInterface</hardwareInterface>
    </joint>
    <actuator name="joint2_motor">
      <mechanicalReduction>1</mechanicalReduction>
    </actuator>
  </transmission>
  <link name="rightshoulder">
    <collision>
      <origin rpy="0 0 0" xyz="0 0 0"/>
      <geometry>
        <mesh filename="package://hdt_michigan_description/meshes/SHOULDER_BRACKET.STL" scale="1.0 1.0 1.0"/>
      </geometry>
    </collision>
    <visual>
      <origin rpy="0 0 0" xyz="0 0 0"/>
      <geometry>
        <mesh filename="package://hdt_michigan_description/meshes/SHOULDER_BRACKET.STL"/>
      </geometry>
      <material name="maize"/>
    </visual>
    <inertial>
      <origin rpy="0 0 0" xyz="0.00013570 -0.04958110 0.01659126"/>
      <mass value="0.48998269"/>
      <inertia ixx="0.00124111" ixy="-0.00000083" ixz="-0.00000019" iyy="0.00020695" iyz="0.00001359" izz="0.00132624"/>
    </inertial>
  </link>
  <!-- Drive 3 -->
  <joint name="rightshoulder" type="fixed">
    <origin rpy="-1.5707963267948966 0 0" xyz="0 -.1 .07526"/>
    <parent link="rightshoulder"/>
    <child link="drive3"/>
  </joint>
  <link name="drive3">
    <collision>
      <origin rpy="0 0 0" xyz="0 0 0"/>
      <geometry>
        <mesh filename="package://hdt_michigan_description/meshes/MK4_LT.STL" scale="1.0 1.0 1.0"/>
      </geometry>
    </collision>
    <visual>
      <origin rpy="0 0 0" xyz="0 0 0"/>
      <geometry>
        <mesh filename="package://hdt_michigan_description/meshes/MK4_LT.STL"/>
      </geometry>
      <material name="blue"/>
    </visual>
    <inertial>
      <origin rpy="0 0 0" xyz="-0.00003658 0.00177045 0.00631346"/>
      <mass value="1.39278013"/>
      <inertia ixx="0.00159582" ixy="-0.00000077" ixz="-0.00000081" iyy="0.00151230" iyz="-0.00002261" izz="0.00105406"/>
    </inertial>
  </link>
  <!-- Right Proximal tube -->
  <joint name="joint3" type="revolute">
    <hdt id="3" inertia="0.1" kmax="200" kmin="100"/>
    <axis xyz="0 0 -1"/>
    <limit effort="90.0" lower="-6.2" upper="6.2" velocity="0.45"/>
    <origin rpy="-3.141592653589793 0 3.141592653589793" xyz="0 0 -.115888"/>
    <parent link="drive3"/>
    <child link="righttube"/>
    <dynamics damping="0.5" friction="0.01"/>
  </joint>
  <transmission name="joint3_transmissions">
    <type>transmission_interface/SimpleTransmission</type>
    <joint name="joint3">
      <hardwareInterface>hardware_interface/PositionJointInterface</hardwareInterface>
    </joint>
    <actuator name="joint3_motor">
      <mechanicalReduction>1</mechanicalReduction>
    </actuator>
  </transmission>
  <link name="righttube">
    <collision>
      <origin rpy="0 1.5707963267948966 0" xyz="0 0 0"/>
      <geometry>
        <mesh filename="package://hdt_michigan_description/meshes/PROXIMAL_TUBE.STL" scale="1.0 1.0 1.0"/>
      </geometry>
    </collision>
    <visual>
      <origin rpy="0 1.5707963267948966 0" xyz="0 0 0"/>
      <geometry>
        <mesh filename="package://hdt_michigan_description/meshes/PROXIMAL_TUBE.STL"/>
      </geometry>
      <material name="maize"/>
    </visual>
    <inertial>
      <origin rpy="0 0 0" xyz="-0.00003112 0.00004034 -0.06064495"/>
      <mass value="0.30359918"/>
      <inertia ixx="0.00099336" ixy="0.00000000" ixz="-0.00000021" iyy="0.00099312" iyz="-0.00000024" izz="0.00020564"/>
    </inertial>
  </link>
  <!-- Drive 4 -->
  <joint name="righttube" type="fixed">
    <origin rpy="-1.5707963267948966 0 1.5707963267948966" xyz="0 0 0.0486304"/>
    <parent link="righttube"/>
    <child link="drive4"/>
  </joint>
  <link name="drive4">
    <collision>
      <origin rpy="0 0 0" xyz="0 0 0"/>
      <geometry>
        <mesh filename="package://hdt_michigan_description/meshes/MK4_LT.STL" scale="1.0 1.0 1.0"/>
      </geometry>
    </collision>
    <visual>
      <origin rpy="0 0 0" xyz="0 0 0"/>
      <geometry>
        <mesh filename="package://hdt_michigan_description/meshes/MK4_LT.STL"/>
      </geometry>
      <material name="blue"/>
    </visual>
    <inertial>
      <origin rpy="0 0 0" xyz="-0.00003658 0.00177045 0.00631346"/>
      <mass value="1.39278013"/>
      <inertia ixx="0.00159582" ixy="-0.00000077" ixz="-0.00000081" iyy="0.00151230" iyz="-0.00002261" izz="0.00105406"/>
    </inertial>
  </link>
  <!-- Right Forearm bracket -->
  <joint name="joint4" type="revolute">
    <hdt id="4" inertia="0.1" kmax="200" kmin="100"/>
    <axis xyz="0 0 -1"/>
    <limit effort="90.0" lower="-3.141592653589793" upper="1.0" velocity="0.45"/>
    <origin rpy="0 0 -1.5707963267948966" xyz="0 0 -.06758"/>
    <parent link="drive4"/>
    <child link="rightforearm"/>
    <dynamics damping="0.1" friction="0.01"/>
  </joint>
  <transmission name="joint4_transmissions">
    <type>transmission_interface/SimpleTransmission</type>
    <joint name="joint4">
      <hardwareInterface>hardware_interface/PositionJointInterface</hardwareInterface>
    </joint>
    <actuator name="joint4_motor">
      <mechanicalReduction>1</mechanicalReduction>
    </actuator>
  </transmission>
  <link name="rightforearm">
    <collision>
      <origin rpy="0 0 0" xyz="0 0 0"/>
      <geometry>
        <mesh filename="package://hdt_michigan_description/meshes/FOREARM_BRACKET.STL" scale="1.0 1.0 1.0"/>
      </geometry>
    </collision>
    <visual>
      <origin rpy="0 0 0" xyz="0 0 0"/>
      <geometry>
        <mesh filename="package://hdt_michigan_description/meshes/FOREARM_BRACKET.STL"/>
      </geometry>
      <material name="maize"/>
    </visual>
    <inertial>
      <origin rpy="0 0 0" xyz="-0.00009916 -0.03803734 0.01245969"/>
      <mass value="0.29009416"/>
      <inertia ixx="0.00060152" ixy="-0.00000038" ixz="0.00000003" iyy="0.00009927" iyz="-0.00000788" izz="0.00065009"/>
    </inertial>
  </link>
  <!-- Drive 5 -->
  <joint name="rightforearm" type="fixed">
    <origin rpy="-1.5707963267948966 0 0" xyz="0 -.17 0.05749"/>
    <parent link="rightforearm"/>
    <child link="drive5"/>
  </joint>
  <link name="drive5">
    <collision>
      <origin rpy="0 0 0" xyz="0 0 0"/>
      <geometry>
        <mesh filename="package://hdt_michigan_description/meshes/A35_DRIVE.STL" scale="1.0 1.0 1.0"/>
      </geometry>
    </collision>
    <visual>
      <origin rpy="0 0 0" xyz="0 0 0"/>
      <geometry>
        <mesh filename="package://hdt_michigan_description/meshes/A35_DRIVE.STL"/>
      </geometry>
      <material name="blue"/>
    </visual>
    <inertial>
      <origin rpy="0 0 0" xyz="0.00000913 0.00110529 -0.01094052"/>
      <mass value="0.30279069"/>
      <inertia ixx="0.00012394" ixy="-0.00000001" ixz="-0.00000007" iyy="0.00011824" iyz="0.00000325" izz="0.00008729"/>
    </inertial>
  </link>
  <!-- Drive 6 -->
  <joint name="joint5" type="revolute">
    <hdt id="5" inertia="0.1" kmax="200" kmin="100"/>
    <axis xyz="0 1 0"/>
    <limit effort="35.0" lower="-6.2" upper="6.2" velocity="2.0943951023931953"/>
    <origin rpy="1.5707963267948966 0 -1.5707963267948966" xyz="0 0 -.067262"/>
    <parent link="drive5"/>
    <child link="drive6"/>
    <dynamics damping="0.01" friction="0.01"/>
  </joint>
  <transmission name="joint5_transmissions">
    <type>transmission_interface/SimpleTransmission</type>
    <joint name="joint5">
      <hardwareInterface>hardware_interface/PositionJointInterface</hardwareInterface>
    </joint>
    <actuator name="joint5_motor">
      <mechanicalReduction>1</mechanicalReduction>
    </actuator>
  </transmission>
  <link name="drive6">
    <collision>
      <origin rpy="0 0 0" xyz="0 0 0"/>
      <geometry>
        <mesh filename="package://hdt_michigan_description/meshes/A35_DRIVE.STL" scale="1.0 1.0 1.0"/>
      </geometry>
    </collision>
    <visual>
      <origin rpy="0 0 0" xyz="0 0 0"/>
      <geometry>
        <mesh filename="package://hdt_michigan_description/meshes/A35_DRIVE.STL"/>
      </geometry>
      <material name="blue"/>
    </visual>
    <inertial>
      <origin rpy="0 0 0" xyz="0.00000913 0.00110529 -0.01094052"/>
      <mass value="0.30279069"/>
      <inertia ixx="0.00012394" ixy="-0.00000001" ixz="-0.00000007" iyy="0.00011824" iyz="0.00000325" izz="0.00008729"/>
    </inertial>
  </link>
  <!-- Right Wrist -->
  <joint name="joint6" type="revolute">
    <hdt id="6" inertia="0.1" kmax="200" kmin="100"/>
    <axis xyz="0 0 -1"/>
    <limit effort="35.0" lower="-1.5707963267948966" upper="1.5707963267948966" velocity="2.0943951023931953"/>
    <origin rpy="0 0 0" xyz="0 0 -.0566728"/>
    <parent link="drive6"/>
    <child link="rightwrist"/>
    <dynamics damping="0.01" friction="0.01"/>
  </joint>
  <transmission name="joint6_transmissions">
    <type>transmission_interface/SimpleTransmission</type>
    <joint name="joint6">
      <hardwareInterface>hardware_interface/PositionJointInterface</hardwareInterface>
    </joint>
    <actuator name="joint6_motor">
      <mechanicalReduction>1</mechanicalReduction>
    </actuator>
  </transmission>
  <link name="rightwrist">
    <collision>
      <origin rpy="0 0 0" xyz="0 0 0"/>
      <geometry>
        <mesh filename="package://hdt_michigan_description/meshes/A35_BRACKET.STL" scale="1.0 1.0 1.0"/>
      </geometry>
    </collision>
    <visual>
      <origin rpy="0 0 0" xyz="0 0 0"/>
      <geometry>
        <mesh filename="package://hdt_michigan_description/meshes/A35_BRACKET.STL"/>
      </geometry>
      <material name="maize"/>
    </visual>
    <inertial>
      <origin rpy="0 0 0" xyz="-0.00001212 -0.02930845 0.01300716"/>
      <mass value="0.14250708"/>
      <inertia ixx="0.00011554" ixy="0.00000005" ixz="-0.00000003" iyy="0.00003814" iyz="-0.00000988" izz="0.00012738"/>
    </inertial>
  </link>
  <!-- Drive 7 -->
  <joint name="rightwrist" type="fixed">
    <origin rpy="-1.5707963267948966 0 0" xyz="0 -.05 .0566728"/>
    <parent link="rightwrist"/>
    <child link="drive7"/>
  </joint>
  <link name="drive7">
    <collision>
      <origin rpy="0 0 0" xyz="0 0 0"/>
      <geometry>
        <mesh filename="package://hdt_michigan_description/meshes/A35_DRIVE.STL" scale="1.0 1.0 1.0"/>
      </geometry>
    </collision>
    <visual>
      <origin rpy="0 0 0" xyz="0 0 0"/>
      <geometry>
        <mesh filename="package://hdt_michigan_description/meshes/A35_DRIVE.STL"/>
      </geometry>
      <material name="blue"/>
    </visual>
    <inertial>
      <origin rpy="0 0 0" xyz="0.00000913 0.00110529 -0.01094052"/>
      <mass value="0.30279069"/>
      <inertia ixx="0.00012394" ixy="-0.00000001" ixz="-0.00000007" iyy="0.00011824" iyz="0.00000325" izz="0.00008729"/>
    </inertial>
  </link>
  <!-- Right Pincer Housing -->
  <joint name="joint7" type="revolute">
    <hdt id="7" inertia="0.1" kmax="200" kmin="100"/>
    <axis xyz="0 0 -1"/>
    <limit effort="35.0" lower="-6.2" upper="6.2" velocity="3.141592653589793"/>
    <origin rpy="3.141592653589793 0 0" xyz="0 0 -.036"/>
    <parent link="drive7"/>
    <child link="drive10"/>
    <dynamics damping="0.01" friction="0.01"/>
  </joint>
  <transmission name="joint7_transmissions">
    <type>transmission_interface/SimpleTransmission</type>
    <joint name="joint7">
      <hardwareInterface>hardware_interface/PositionJointInterface</hardwareInterface>
    </joint>
    <actuator name="joint7_motor">
      <mechanicalReduction>1</mechanicalReduction>
    </actuator>
  </transmission>
  <link name="drive10">
    </link>
  <joint name="housing_right" type="fixed">
    <origin rpy="0 0 0" xyz="0 0 0"/>
    <parent link="drive10"/>
    <child link="end_effector_right"/>
  </joint>
  <link name="end_effector_right">
    <collision>
      <origin rpy="0 0 0" xyz="0 0 0"/>
      <geometry>
        <mesh filename="package://hdt_michigan_description/meshes/PINCER_HOUSING2.STL" scale="1.0 1.0 1.0"/>
      </geometry>
    </collision>
    <collision>
      <origin rpy="0 0 0" xyz="0.0625 0 0.045"/>
      <geometry>
        <box size="0.03 0.10 0.10"/>
      </geometry>
    </collision>
    <visual>
      <origin rpy="0 0 0" xyz="0 0 0"/>
      <geometry>
        <mesh filename="package://hdt_michigan_description/meshes/PINCER_HOUSING2.STL"/>
      </geometry>
      <material name="maize"/>
    </visual>
    <inertial>
      <origin rpy="-1.5707963267948966 0 0" xyz="-0.02828166 0.00000247 -0.01722827"/>
      <mass value="0.27265869"/>
      <inertia ixx="0.00009278" ixy="0.0" ixz="0.00000608" iyy="0.00010001" iyz="0.0" izz="0.00007523"/>
    </inertial>
  </link>
  <!-- Right Pincers-->
  <joint name="rightgripper" type="revolute">
    <hdt id="10a" inertia="0.075" kmax="150" kmin="75"/>
    <axis xyz="0 0 1"/>
    <limit effort="35.0" lower="-0.1166" upper="1" velocity="0.5"/>
    <origin rpy="1.5707963267948966 -0.42 -1.5707963267948966" xyz="0 0.0135 0.068553"/>
    <parent link="end_effector_right"/>
    <child link="rightgripper_link"/>
    <dynamics damping="0.01" friction="0"/>
  </joint>
  <transmission name="rightgripper_transmissions">
    <type>transmission_interface/SimpleTransmission</type>
    <joint name="rightgripper">
      <hardwareInterface>hardware_interface/PositionJointInterface</hardwareInterface>
    </joint>
    <actuator name="rightgripper_motor">
      <mechanicalReduction>1</mechanicalReduction>
    </actuator>
  </transmission>
  <link name="rightgripper_link">
    <collision>
      <origin rpy="0 0 0" xyz="0 0 0"/>
      <geometry>
        <mesh filename="package://hdt_michigan_description/meshes/PINCER_FINGER.STL" scale="1.0 1.0 1.0"/>
      </geometry>
    </collision>
    <visual>
      <origin rpy="0 0 0" xyz="0 0 0"/>
      <geometry>
        <mesh filename="package://hdt_michigan_description/meshes/PINCER_FINGER.STL"/>
      </geometry>
      <material name="blue"/>
    </visual>
    <inertial>
      <origin rpy="0 0 0" xyz="0.034 0.055 0.007"/>
      <mass value="0.06821764"/>
      <inertia ixx="0.00007499" ixy="0" ixz="0" iyy="0.00002842" iyz="0" izz="0.00010118"/>
    </inertial>
  </link>
  <!-- Right EE 2 -->
  <!-- THIS IS THE SECOND PINCER, NEEDS TO MOVE EQUAL BUT OPPOSITE AS PINCER 1 -->
  <joint name="rightgripper2" type="revolute">
    <hdt id="10b" inertia="0.075" kmax="150" kmin="75"/>
    <axis xyz="0 0 1"/>
    <origin rpy="1.5707963267948966 -0.42 1.5707963267948966" xyz="0 -0.0135 0.068553"/>
    <parent link="end_effector_right"/>
    <child link="rightgripper2_link"/>
    <calibration rising="0.0"/>
    <dynamics damping="0.01" friction="0"/>
    <limit effort="35.0" lower="-0.116" upper="1" velocity="0.5"/>
  </joint>
  <transmission name="rightgripper2_transmissions">
    <type>transmission_interface/SimpleTransmission</type>
    <joint name="rightgripper2">
      <hardwareInterface>hardware_interface/PositionJointInterface</hardwareInterface>
    </joint>
    <actuator name="rightgripper2_motor">
      <mechanicalReduction>1</mechanicalReduction>
    </actuator>
  </transmission>
  <link name="rightgripper2_link">
    <collision>
      <origin rpy="0 0 0" xyz="0 0 0"/>
      <geometry>
        <mesh filename="package://hdt_michigan_description/meshes/PINCER_FINGER.STL" scale="1.0 1.0 1.0"/>
      </geometry>
    </collision>
    <visual>
      <origin rpy="0 0 0" xyz="0 0 0"/>
      <geometry>
        <mesh filename="package://hdt_michigan_description/meshes/PINCER_FINGER.STL"/>
      </geometry>
      <material name="blue"/>
    </visual>
    <inertial>
      <origin rpy="0 0 0" xyz="0.034 0.055 0.007"/>
      <mass value="0.06821764"/>
      <inertia ixx="0.00007499" ixy="0" ixz="0" iyy="0.00002842" iyz="0" izz="0.00010118"/>
    </inertial>
  </link>
  <!-- NOTE: defining tools here allows moveit to plan with respect to these frames very easily.
      I think it makes sense to leave this file un-modified on shared accounts, and overwrite the robot description
      on the parameter server from your local modified copy on a personal account. -->
  <link name="left_tool">
    <visual name="left_tool_visual">
      <origin rpy="0 0 0" xyz="0 0 0"/>
      <geometry>
        <sphere radius="0.002"/>
      </geometry>
    </visual>
    <inertial>
      <origin rpy="0 0 0" xyz="0 0 0"/>
      <mass value="0.001"/>
      <inertia ixx="0" ixy="0" ixz="0" iyy="0" iyz="0" izz="0"/>
    </inertial>
  </link>
  <joint name="left_tool_joint" type="fixed">
    <parent link="end_effector_left"/>
    <child link="left_tool"/>
    <origin rpy="0 0 0" xyz="0.0 0.0 0.181"/>
  </joint>
  <link name="right_tool">
    <visual name="right_tool_visual">
      <origin rpy="0 0 0" xyz="0 0 0"/>
      <geometry>
        <sphere radius="0.002"/>
      </geometry>
    </visual>
    <inertial>
      <origin rpy="0 0 0" xyz="0 0 0"/>
      <mass value="0.001"/>
      <inertia ixx="0" ixy="0" ixz="0" iyy="0" iyz="0" izz="0"/>
    </inertial>
  </link>
  <joint name="right_tool_joint" type="fixed">
    <parent link="end_effector_right"/>
    <child link="right_tool"/>
    <origin rpy="0 0 0" xyz="0.0 0.0 0.181"/>
  </joint>
  <gazebo>
    <plugin filename="libgazebo_ros_control.so" name="gazebo_ros_control">
      <robotNamespace>hdt_michigan</robotNamespace>
      <legacyModeNS>false</legacyModeNS>
    </plugin>
  </gazebo>
  <gazebo>
    <plugin filename="libgazebo_ros_moveit_planning_scene.so" name="gazebo_ros_moveit_planning_scene">
      <robotName>hdt_michigan</robotName>
      <robotNamespace>hdt_michigan</robotNamespace>
      <!--  This must be the same as the root frame of the robot you're using -->
      <frameId>hdt_michigan_root</frameId>
      <excludedModels>collision_sphere my_ground_plane</excludedModels>
      <scalePrimitivesFactor>1.0</scalePrimitivesFactor>
    </plugin>
  </gazebo>
</robot>
